Workbook
Name _dave005: #REF!
Name _dave005: #REF!
Name _dave005: #REF!
Name _jas005: #REF!
Name _jas005: #REF!
Name _jas005: #REF!
Name _jas006: #REF!
Name _jas006: #REF!
Name _jas006: #REF!
Name _jas007: #REF!
Name _jas007: #REF!
Name _jas007: #REF!
Name _john005: #REF!
Name _john005: #REF!
Name _john005: #REF!
Name _sam005: #REF!
Name _sam005: #REF!
Name _sam005: #REF!
Name exchange_rate: [1]Data!$C$272
Name myCurviness: '[2]SUBSCRIBER NORMALIZATION'!$C$12
Name myCurviness: '[2]SUBSCRIBER NORMALIZATION'!$C$12
Name myCurviness: '[2]SUBSCRIBER NORMALIZATION'!$C$12
Name myCurviness: '[2]SUBSCRIBER NORMALIZATION'!$C$12
Name myCurviness: 'SUBSCRIBER NORMALIZATION'!$C$12
Name myCurviness1: #REF!
Name myReferenceBand: 'SUBSCRIBER NORMALIZATION'!#REF!
Name myReferenceBand: 'SUBSCRIBER NORMALIZATION FLTE'!#REF!
Name myReferenceBand: 'SUBSCRIBER NORMALIZATION'!#REF!
Name myReferenceBand: 'SUBSCRIBER NORMALIZATION FLTE'!#REF!
Name myReferenceBand: '[2]SUBSCRIBER NORMALIZATION'!#REF!
Name myReferenceBand: '[2]SUBSCRIBER NORMALIZATION'!#REF!
Name myReferenceBand: '[2]SUBSCRIBER NORMALIZATION'!#REF!
Name myReferenceBand: '[2]SUBSCRIBER NORMALIZATION'!#REF!
Name myReferenceBand: 'SUBSCRIBER NORMALIZATION'!#REF!
Name myReferenceBand: #REF!
Name myReferenceBand: 'SUBSCRIBER NORMALIZATION FLTE'!#REF!
Name myReferenceBand: 'SUBSCRIBER NORMALIZATION'!#REF!
Name myReferenceBand: 'SUBSCRIBER NORMALIZATION FLTE'!#REF!
Name myReferenceBand: 'SUBSCRIBER NORMALIZATION'!#REF!
Name myReferenceBand: 'SUBSCRIBER NORMALIZATION FLTE'!#REF!
Name myReferenceBand: 'SUBSCRIBER NORMALIZATION'!#REF!
Name myReferenceBand: 'SUBSCRIBER NORMALIZATION FLTE'!#REF!
Name myReferenceBand: 'SUBSCRIBER NORMALIZATION'!#REF!
Name myReferenceBand: 'SUBSCRIBER NORMALIZATION FLTE'!#REF!
Name myReferenceBand: 'SUBSCRIBER NORMALIZATION'!#REF!
Name myReferenceBand: 'SUBSCRIBER NORMALIZATION FLTE'!#REF!
Name myReferenceBand: 'SUBSCRIBER NORMALIZATION'!#REF!
Name myReferenceBand: 'SUBSCRIBER NORMALIZATION FLTE'!#REF!
Name myReferenceBand: 'SUBSCRIBER NORMALIZATION'!#REF!
Name myReferenceBand: 'SUBSCRIBER NORMALIZATION FLTE'!#REF!
Name myReferenceBand: 'SUBSCRIBER NORMALIZATION'!#REF!
Name myReferenceBand1: #REF!
Name myStartofFastGrowth: '[2]SUBSCRIBER NORMALIZATION'!$C$10
Name myStartofFastGrowth: '[2]SUBSCRIBER NORMALIZATION'!$C$10
Name myStartofFastGrowth: '[2]SUBSCRIBER NORMALIZATION'!$C$10
Name myStartofFastGrowth: '[2]SUBSCRIBER NORMALIZATION'!$C$10
Name myStartofFastGrowth: 'SUBSCRIBER NORMALIZATION'!$C$10
Name myStartofFastGrowth1: #REF!
Name myStartValue: '[2]SUBSCRIBER NORMALIZATION'!$C$8
Name myStartValue: '[2]SUBSCRIBER NORMALIZATION'!$C$8

Sheet <<KEY FINANCIAL INDICATORS> TOT
B3: =UPPER('<<VERSIONING NOTES>>'!$F$2)&TEXT(" KEY FINANCIAL INDICATORS VERSION ","")&'<<VERSIONING NOTES>>'!$F$3 -> METL KEY FINANCIAL INDICATORS VERSION MVNE Financial Framework Template Metl 20250604 1m | H3: =TEXT("Prepared by ","") -> Prepared by
H4: ='<<VERSIONING NOTES>>'!F4 -> Edward Wicks | J4: 0.08
J5: =H26/2300000 -> 0.96636954
C6: Rewards value | D6: Projected | E6: Cumulative EBIT | F6: Cash Flow First | G6: Cash Flow First | H6: Cumulative Revenue
C7: Generated | D7: Peak Funding | E7: over 60 Months | F7: Positive in Month | G7: BreakEven in Month | H7: Over 60 Months
C8: ='<<KEY FINANCIAL INDICATORS>>'!C8+'<<KEY FINANCIAL INDICATORS>FLTE'!C8 -> 1.3007635e+10 | D8: =ABS(MIN('<<CASH FLOW PROJECTIONS>> TOT'!C62:BR62)) -> 7.718054e+09 | E8: =H21 -> 4.0569124e+10 | F8: =MIN('<<CASH FLOW PROJECTIONS>> TOT'!C64:BR64) -> 25 | G8: =MIN('<<CASH FLOW PROJECTIONS>> TOT'!C65:BR65) -> 35 | H8: =SUM('<<CASH FLOW PROJECTIONS>> TOT'!C8:BR8) -> 4.3358782e+11
B10: Projections | C10: Project Phase | D10: Year 1 | E10: Year 2 | F10: Year 3 | G10: Year 4 | H10: Year 5
B12: Revenue | C12: =SUM('<<CASH FLOW PROJECTIONS>> TOT'!C8:H8) -> 0 | D12: =SUM('<<CASH FLOW PROJECTIONS>> TOT'!I8:V8) -> 8.7970996e+09 | E12: =SUM('<<CASH FLOW PROJECTIONS>> TOT'!W8:AH8) -> 3.7571707e+10 | F12: =SUM('<<CASH FLOW PROJECTIONS>> TOT'!AI8:AT8) -> 9.6092394e+10 | G12: =SUM('<<CASH FLOW PROJECTIONS>> TOT'!AU8:BF8) -> 1.2897483e+11 | H12: =SUM('<<CASH FLOW PROJECTIONS>> TOT'!BG8:BR8) -> 1.6215179e+11
B13: Direct Costs | C13: =SUM('<<CASH FLOW PROJECTIONS>> TOT'!C20:H20) -> 0 | D13: =SUM('<<CASH FLOW PROJECTIONS>> TOT'!I20:V20) -> 1.0274608e+10 | E13: =SUM('<<CASH FLOW PROJECTIONS>> TOT'!W20:AH20) -> 3.7047177e+10 | F13: =SUM('<<CASH FLOW PROJECTIONS>> TOT'!AI20:AT20) -> 8.1531382e+10 | G13: =SUM('<<CASH FLOW PROJECTIONS>> TOT'!AU20:BF20) -> 1.0794837e+11 | H13: =SUM('<<CASH FLOW PROJECTIONS>> TOT'!BG20:BR20) -> 1.2860298e+11
B14: Gross Profit | C14: =C12-C13 -> 0 | D14: =D12-D13 -> -1.4775087e+09 | E14: =E12-E13 -> 5.2453033e+08 | F14: =F12-F13 -> 1.4561011e+10 | G14: =G12-G13 -> 2.1026459e+10 | H14: =H12-H13 -> 3.3548815e+10
B15: Operational Expenditure | C15: =SUM('<<CASH FLOW PROJECTIONS>> TOT'!C39:H39) -> 1764000000 | D15: =SUM('<<CASH FLOW PROJECTIONS>> TOT'!I39:V39) -> 1.3117959e+09 | E15: =SUM('<<CASH FLOW PROJECTIONS>> TOT'!W39:AH39) -> 1.4952687e+09 | F15: =SUM('<<CASH FLOW PROJECTIONS>> TOT'!AI39:AT39) -> 2.1413438e+09 | G15: =SUM('<<CASH FLOW PROJECTIONS>> TOT'!AU39:BF39) -> 2.5347536e+09 | H15: =SUM('<<CASH FLOW PROJECTIONS>> TOT'!BG39:BR39) -> 2.9351265e+09
B16: EBITDA | C16: =C14-C15 -> -1764000000 | D16: =D14-D15 -> -2.7893046e+09 | E16: =E14-E15 -> -9.7073835e+08 | F16: =F14-F15 -> 1.2419668e+10 | G16: =G14-G15 -> 1.8491706e+10 | H16: =H14-H15 -> 3.0613689e+10
B17: Capital Expenditure | C17: =SUM('<<CASH FLOW PROJECTIONS>> TOT'!C47:H47) -> 608300000 | D17: =SUM('<<CASH FLOW PROJECTIONS>> TOT'!I47:V47) -> 500000 | E17: =SUM('<<CASH FLOW PROJECTIONS>> TOT'!W47:AH47) -> 0 | F17: =SUM('<<CASH FLOW PROJECTIONS>> TOT'!AI47:AT47) -> 0 | G17: =SUM('<<CASH FLOW PROJECTIONS>> TOT'!AU47:BF47) -> 0 | H17: =SUM('<<CASH FLOW PROJECTIONS>> TOT'!BG47:BR47) -> 0
B18: Depreciation | C18: 0 | D18: 0 | E18: 0 | F18: 0 | G18: 0 | H18: 0
B19: Provisions | C19: =SUM('<<CASH FLOW PROJECTIONS>> TOT'!C55:H55) -> 0 | D19: =SUM('<<CASH FLOW PROJECTIONS>> TOT'!I55:V55) -> 3.0074266e+08 | E19: =SUM('<<CASH FLOW PROJECTIONS>> TOT'!W55:AH55) -> 1.2844684e+09 | F19: =SUM('<<CASH FLOW PROJECTIONS>> TOT'!AI55:AT55) -> 3.2848761e+09 | G19: =SUM('<<CASH FLOW PROJECTIONS>> TOT'!AU55:BF55) -> 4.4093023e+09 | H19: =SUM('<<CASH FLOW PROJECTIONS>> TOT'!BG55:BR55) -> 5.5437052e+09
B20: EBIT | C20: =C16-C17-C18-C19 -> -2372300000 | D20: =D16-D17-D18-D19 -> -3.0905472e+09 | E20: =E16-E17-E18-E19 -> -2.2552067e+09 | F20: =F16-F17-F18-F19 -> 9.1347915e+09 | G20: =G16-G17-G18-G19 -> 1.4082403e+10 | H20: =H16-H17-H18-H19 -> 2.5069983e+10
B21: CUMULATIVE EBIT | C21: =C20 -> -2372300000 | D21: =D20+C21 -> -5.4628472e+09 | E21: =E20+D21 -> -7.718054e+09 | F21: =F20+E21 -> 1.4167376e+09 | G21: =G20+F21 -> 1.5499141e+10 | H21: =H20+G21 -> 4.0569124e+10
B22: Value of the base | D22: =D28*D27*24 -> 2.0743442e+10 | E22: =E28*E27*24 -> 6.4314685e+10 | F22: =F28*F27*24 -> 1.293656e+11 | G22: =G28*G27*24 -> 1.5605553e+11 | H22: =H28*H27*24 -> 1.9373755e+11
C23: Susbcriber Base | D23: Year 1 | E23: Year 2 | F23: Year 3 | G23: Year 4 | H23: Year 5
C24: Conversion for the year | D24: =D27/'ACQUISITION ASSUMPTIONS'!$C$10 -> 0.029814514 | E24: =(E26-E25)/'ACQUISITION ASSUMPTIONS'!$C$10 -> 0.062859728 | F24: =(F26-F25)/'ACQUISITION ASSUMPTIONS'!$C$10 -> 0.056453685 | G24: =(G26-G25)/'ACQUISITION ASSUMPTIONS'!$C$10 -> 0.034207249 | H24: =(H26-H25)/'ACQUISITION ASSUMPTIONS'!$C$10 -> 0.020280978
C25: Opening Base | D25: ='<<KEY FINANCIAL INDICATORS>>'!D27+'<<KEY FINANCIAL INDICATORS>FLTE'!D25 -> 0 | E25: ='<<KEY FINANCIAL INDICATORS>>'!E27+'<<KEY FINANCIAL INDICATORS>FLTE'!E25 -> 325605.03 | F25: ='<<KEY FINANCIAL INDICATORS>>'!F27+'<<KEY FINANCIAL INDICATORS>FLTE'!F25 -> 1011719 | G25: ='<<KEY FINANCIAL INDICATORS>>'!G27+'<<KEY FINANCIAL INDICATORS>FLTE'!G25 -> 1627910.9 | H25: ='<<KEY FINANCIAL INDICATORS>>'!H27+'<<KEY FINANCIAL INDICATORS>FLTE'!H25 -> 2001283.1
C26: Closing Base | D26: ='<<KEY FINANCIAL INDICATORS>>'!D28+'<<KEY FINANCIAL INDICATORS>FLTE'!D26 -> 325605.03 | E26: ='<<KEY FINANCIAL INDICATORS>>'!E28+'<<KEY FINANCIAL INDICATORS>FLTE'!E26 -> 1011719 | F26: ='<<KEY FINANCIAL INDICATORS>>'!F28+'<<KEY FINANCIAL INDICATORS>FLTE'!F26 -> 1627910.9 | G26: ='<<KEY FINANCIAL INDICATORS>>'!G28+'<<KEY FINANCIAL INDICATORS>FLTE'!G26 -> 2001283.1 | H26: ='<<KEY FINANCIAL INDICATORS>>'!H28+'<<KEY FINANCIAL INDICATORS>FLTE'!H26 -> 2222649.9
C27: Active Base | D27: ='<<KEY FINANCIAL INDICATORS>>'!D29+'<<KEY FINANCIAL INDICATORS>FLTE'!D27 -> 325425.42 | E27: ='<<KEY FINANCIAL INDICATORS>>'!E29+'<<KEY FINANCIAL INDICATORS>FLTE'!E27 -> 1011092.8 | F27: ='<<KEY FINANCIAL INDICATORS>>'!F29+'<<KEY FINANCIAL INDICATORS>FLTE'!F27 -> 1626729.1 | G27: ='<<KEY FINANCIAL INDICATORS>>'!G29+'<<KEY FINANCIAL INDICATORS>FLTE'!G27 -> 1965339.1 | H27: ='<<KEY FINANCIAL INDICATORS>>'!H29+'<<KEY FINANCIAL INDICATORS>FLTE'!H27 -> 2220484.7
C28: Blended ARPU | D28: =('<<KEY FINANCIAL INDICATORS>>'!D30+'<<KEY FINANCIAL INDICATORS>FLTE'!D28)/2 -> 2655.939 | E28: =('<<KEY FINANCIAL INDICATORS>>'!E30+'<<KEY FINANCIAL INDICATORS>FLTE'!E28)/2 -> 2650.3783 | F28: =('<<KEY FINANCIAL INDICATORS>>'!F30+'<<KEY FINANCIAL INDICATORS>FLTE'!F28)/2 -> 3313.5409 | G28: =('<<KEY FINANCIAL INDICATORS>>'!G30+'<<KEY FINANCIAL INDICATORS>FLTE'!G28)/2 -> 3308.4946 | H28: =('<<KEY FINANCIAL INDICATORS>>'!H30+'<<KEY FINANCIAL INDICATORS>FLTE'!H28)/2 -> 3635.4216
C29: CAGR % | E29: =IF(E28>0,(E28-D28)/D28,0) -> -0.0020936906 | F29: =IF(F28>0,(F28-E28)/E28,0) -> 0.25021431 | G29: =IF(G28>0,(G28-F28)/F28,0) -> -0.0015229462 | H29: =IF(H28>0,(H28-G28)/G28,0) -> 0.098814432

Sheet <<CASH FLOW PROJECTIONS>> TOT
B3: =UPPER('<<VERSIONING NOTES>>'!$F$2)&TEXT(" CASH FLOW PROJECTIONS VERSION ","")&'<<VERSIONING NOTES>>'!$F$3 -> METL CASH FLOW PROJECTIONS VERSION MVNE Financial Framework Template Metl 20250604 1m | BR3: =TEXT("Prepared by ","") -> Prepared by
BR4: ='<<VERSIONING NOTES>>'!F4 -> Edward Wicks
C6: PM1 | D6: PM2 | E6: PM3 | F6: PM4 | G6: PM5 | H6: PM6 | I6: SL1 | J6: SL2 | K6: 1 | L6: 2 | M6: 3 | N6: 4 | O6: 5 | P6: 6 | Q6: 7 | R6: 8 | S6: 9 | T6: 10 | U6: 11 | V6: 12 | W6: 13 | X6: 14 | Y6: 15 | Z6: 16 | AA6: 17 | AB6: 18 | AC6: 19 | AD6: 20 | AE6: 21 | AF6: 22 | AG6: 23 | AH6: 24 | AI6: 25 | AJ6: 26 | AK6: 27 | AL6: 28 | AM6: 29 | AN6: 30 | AO6: 31 | AP6: 32 | AQ6: 33 | AR6: 34 | AS6: 35 | AT6: 36 | AU6: 37 | AV6: 38 | AW6: 39 | AX6: 40 | AY6: 41 | AZ6: 42 | BA6: 43 | BB6: 44 | BC6: 45 | BD6: 46 | BE6: 47 | BF6: 48 | BG6: 49 | BH6: 50 | BI6: 51 | BJ6: 52 | BK6: 53 | BL6: 54 | BM6: 55 | BN6: 56 | BO6: 57 | BP6: 58 | BQ6: 59 | BR6: 60
B8: Revenue | C8: =SUM(C9:C19) -> 0 | D8: =SUM(D9:D19) -> 0 | E8: =SUM(E9:E19) -> 0 | F8: =SUM(F9:F19) -> 0 | G8: =SUM(G9:G19) -> 0 | H8: =SUM(H9:H19) -> 0 | I8: =SUM(I9:I19) -> 0 | J8: =SUM(J9:J19) -> 0 | ... BR8: =SUM(BR9:BR19) -> 1.4321841e+10
B9: Connection Fees | C9: ='<<CASH FLOW PROJECTIONS>>'!C9+'<<CASH FLOW PROJECTIONS>>FLTE'!C9 -> 0 | D9: ='<<CASH FLOW PROJECTIONS>>'!D9+'<<CASH FLOW PROJECTIONS>>FLTE'!D9 -> 0 | E9: ='<<CASH FLOW PROJECTIONS>>'!E9+'<<CASH FLOW PROJECTIONS>>FLTE'!E9 -> 0 | F9: ='<<CASH FLOW PROJECTIONS>>'!F9+'<<CASH FLOW PROJECTIONS>>FLTE'!F9 -> 0 | G9: ='<<CASH FLOW PROJECTIONS>>'!G9+'<<CASH FLOW PROJECTIONS>>FLTE'!G9 -> 0 | H9: ='<<CASH FLOW PROJECTIONS>>'!H9+'<<CASH FLOW PROJECTIONS>>FLTE'!H9 -> 0 | I9: ='<<CASH FLOW PROJECTIONS>>'!I9+'<<CASH FLOW PROJECTIONS>>FLTE'!I9 -> 0 | J9: ='<<CASH FLOW PROJECTIONS>>'!J9+'<<CASH FLOW PROJECTIONS>>FLTE'!J9 -> 0 | ... BR9: ='<<CASH FLOW PROJECTIONS>>'!BR9+'<<CASH FLOW PROJECTIONS>>FLTE'!BR9 -> 0
B10: Courier Fees | C10: ='<<CASH FLOW PROJECTIONS>>'!C10+'<<CASH FLOW PROJECTIONS>>FLTE'!C10 -> 0 | D10: ='<<CASH FLOW PROJECTIONS>>'!D10+'<<CASH FLOW PROJECTIONS>>FLTE'!D10 -> 0 | E10: ='<<CASH FLOW PROJECTIONS>>'!E10+'<<CASH FLOW PROJECTIONS>>FLTE'!E10 -> 0 | F10: ='<<CASH FLOW PROJECTIONS>>'!F10+'<<CASH FLOW PROJECTIONS>>FLTE'!F10 -> 0 | G10: ='<<CASH FLOW PROJECTIONS>>'!G10+'<<CASH FLOW PROJECTIONS>>FLTE'!G10 -> 0 | H10: ='<<CASH FLOW PROJECTIONS>>'!H10+'<<CASH FLOW PROJECTIONS>>FLTE'!H10 -> 0 | I10: ='<<CASH FLOW PROJECTIONS>>'!I10+'<<CASH FLOW PROJECTIONS>>FLTE'!I10 -> 0 | J10: ='<<CASH FLOW PROJECTIONS>>'!J10+'<<CASH FLOW PROJECTIONS>>FLTE'!J10 -> 0 | ... BR10: ='<<CASH FLOW PROJECTIONS>>'!BR10+'<<CASH FLOW PROJECTIONS>>FLTE'!BR10 -> 805200
B11: Cash Device Sales Revenue | C11: ='<<CASH FLOW PROJECTIONS>>'!C11+'<<CASH FLOW PROJECTIONS>>FLTE'!C11 -> 0 | D11: ='<<CASH FLOW PROJECTIONS>>'!D11+'<<CASH FLOW PROJECTIONS>>FLTE'!D11 -> 0 | E11: ='<<CASH FLOW PROJECTIONS>>'!E11+'<<CASH FLOW PROJECTIONS>>FLTE'!E11 -> 0 | F11: ='<<CASH FLOW PROJECTIONS>>'!F11+'<<CASH FLOW PROJECTIONS>>FLTE'!F11 -> 0 | G11: ='<<CASH FLOW PROJECTIONS>>'!G11+'<<CASH FLOW PROJECTIONS>>FLTE'!G11 -> 0 | H11: ='<<CASH FLOW PROJECTIONS>>'!H11+'<<CASH FLOW PROJECTIONS>>FLTE'!H11 -> 0 | I11: ='<<CASH FLOW PROJECTIONS>>'!I11+'<<CASH FLOW PROJECTIONS>>FLTE'!I11 -> 0 | J11: ='<<CASH FLOW PROJECTIONS>>'!J11+'<<CASH FLOW PROJECTIONS>>FLTE'!J11 -> 0 | ... BR11: ='<<CASH FLOW PROJECTIONS>>'!BR11+'<<CASH FLOW PROJECTIONS>>FLTE'!BR11 -> 0
B12: Credit Device Pay in Revenue | C12: ='<<CASH FLOW PROJECTIONS>>'!C12+'<<CASH FLOW PROJECTIONS>>FLTE'!C12 -> 0 | D12: ='<<CASH FLOW PROJECTIONS>>'!D12+'<<CASH FLOW PROJECTIONS>>FLTE'!D12 -> 0 | E12: ='<<CASH FLOW PROJECTIONS>>'!E12+'<<CASH FLOW PROJECTIONS>>FLTE'!E12 -> 0 | F12: ='<<CASH FLOW PROJECTIONS>>'!F12+'<<CASH FLOW PROJECTIONS>>FLTE'!F12 -> 0 | G12: ='<<CASH FLOW PROJECTIONS>>'!G12+'<<CASH FLOW PROJECTIONS>>FLTE'!G12 -> 0 | H12: ='<<CASH FLOW PROJECTIONS>>'!H12+'<<CASH FLOW PROJECTIONS>>FLTE'!H12 -> 0 | I12: ='<<CASH FLOW PROJECTIONS>>'!I12+'<<CASH FLOW PROJECTIONS>>FLTE'!I12 -> 0 | J12: ='<<CASH FLOW PROJECTIONS>>'!J12+'<<CASH FLOW PROJECTIONS>>FLTE'!J12 -> 0 | ... BR12: ='<<CASH FLOW PROJECTIONS>>'!BR12+'<<CASH FLOW PROJECTIONS>>FLTE'!BR12 -> 0
B13: Device Subscription Revenue | C13: ='<<CASH FLOW PROJECTIONS>>'!C13+'<<CASH FLOW PROJECTIONS>>FLTE'!C13 -> 0 | D13: ='<<CASH FLOW PROJECTIONS>>'!D13+'<<CASH FLOW PROJECTIONS>>FLTE'!D13 -> 0 | E13: ='<<CASH FLOW PROJECTIONS>>'!E13+'<<CASH FLOW PROJECTIONS>>FLTE'!E13 -> 0 | F13: ='<<CASH FLOW PROJECTIONS>>'!F13+'<<CASH FLOW PROJECTIONS>>FLTE'!F13 -> 0 | G13: ='<<CASH FLOW PROJECTIONS>>'!G13+'<<CASH FLOW PROJECTIONS>>FLTE'!G13 -> 0 | H13: ='<<CASH FLOW PROJECTIONS>>'!H13+'<<CASH FLOW PROJECTIONS>>FLTE'!H13 -> 0 | I13: ='<<CASH FLOW PROJECTIONS>>'!I13+'<<CASH FLOW PROJECTIONS>>FLTE'!I13 -> 0 | J13: ='<<CASH FLOW PROJECTIONS>>'!J13+'<<CASH FLOW PROJECTIONS>>FLTE'!J13 -> 0 | ... BR13: ='<<CASH FLOW PROJECTIONS>>'!BR13+'<<CASH FLOW PROJECTIONS>>FLTE'!BR13 -> 0
B14: Subscription Revenue | C14: ='<<CASH FLOW PROJECTIONS>>'!C14+'<<CASH FLOW PROJECTIONS>>FLTE'!C14 -> 0 | D14: ='<<CASH FLOW PROJECTIONS>>'!D14+'<<CASH FLOW PROJECTIONS>>FLTE'!D14 -> 0 | E14: ='<<CASH FLOW PROJECTIONS>>'!E14+'<<CASH FLOW PROJECTIONS>>FLTE'!E14 -> 0 | F14: ='<<CASH FLOW PROJECTIONS>>'!F14+'<<CASH FLOW PROJECTIONS>>FLTE'!F14 -> 0 | G14: ='<<CASH FLOW PROJECTIONS>>'!G14+'<<CASH FLOW PROJECTIONS>>FLTE'!G14 -> 0 | H14: ='<<CASH FLOW PROJECTIONS>>'!H14+'<<CASH FLOW PROJECTIONS>>FLTE'!H14 -> 0 | I14: ='<<CASH FLOW PROJECTIONS>>'!I14+'<<CASH FLOW PROJECTIONS>>FLTE'!I14 -> 0 | J14: ='<<CASH FLOW PROJECTIONS>>'!J14+'<<CASH FLOW PROJECTIONS>>FLTE'!J14 -> 0 | ... BR14: ='<<CASH FLOW PROJECTIONS>>'!BR14+'<<CASH FLOW PROJECTIONS>>FLTE'!BR14 -> 1.4321036e+10
B15: OOB Spend Revenue | C15: ='<<CASH FLOW PROJECTIONS>>'!C15+'<<CASH FLOW PROJECTIONS>>FLTE'!C15 -> 0 | D15: ='<<CASH FLOW PROJECTIONS>>'!D15+'<<CASH FLOW PROJECTIONS>>FLTE'!D15 -> 0 | E15: ='<<CASH FLOW PROJECTIONS>>'!E15+'<<CASH FLOW PROJECTIONS>>FLTE'!E15 -> 0 | F15: ='<<CASH FLOW PROJECTIONS>>'!F15+'<<CASH FLOW PROJECTIONS>>FLTE'!F15 -> 0 | G15: ='<<CASH FLOW PROJECTIONS>>'!G15+'<<CASH FLOW PROJECTIONS>>FLTE'!G15 -> 0 | H15: ='<<CASH FLOW PROJECTIONS>>'!H15+'<<CASH FLOW PROJECTIONS>>FLTE'!H15 -> 0 | I15: ='<<CASH FLOW PROJECTIONS>>'!I15+'<<CASH FLOW PROJECTIONS>>FLTE'!I15 -> 0 | J15: ='<<CASH FLOW PROJECTIONS>>'!J15+'<<CASH FLOW PROJECTIONS>>FLTE'!J15 -> 0 | ... BR15: ='<<CASH FLOW PROJECTIONS>>'!BR15+'<<CASH FLOW PROJECTIONS>>FLTE'!BR15 -> 0
B16: Itemized Billing Revenue | C16: ='<<CASH FLOW PROJECTIONS>>'!C16+'<<CASH FLOW PROJECTIONS>>FLTE'!C16 -> 0 | D16: ='<<CASH FLOW PROJECTIONS>>'!D16+'<<CASH FLOW PROJECTIONS>>FLTE'!D16 -> 0 | E16: ='<<CASH FLOW PROJECTIONS>>'!E16+'<<CASH FLOW PROJECTIONS>>FLTE'!E16 -> 0 | F16: ='<<CASH FLOW PROJECTIONS>>'!F16+'<<CASH FLOW PROJECTIONS>>FLTE'!F16 -> 0 | G16: ='<<CASH FLOW PROJECTIONS>>'!G16+'<<CASH FLOW PROJECTIONS>>FLTE'!G16 -> 0 | H16: ='<<CASH FLOW PROJECTIONS>>'!H16+'<<CASH FLOW PROJECTIONS>>FLTE'!H16 -> 0 | I16: ='<<CASH FLOW PROJECTIONS>>'!I16+'<<CASH FLOW PROJECTIONS>>FLTE'!I16 -> 0 | J16: ='<<CASH FLOW PROJECTIONS>>'!J16+'<<CASH FLOW PROJECTIONS>>FLTE'!J16 -> 0 | ... BR16: ='<<CASH FLOW PROJECTIONS>>'!BR16+'<<CASH FLOW PROJECTIONS>>FLTE'!BR16 -> 0
B17: Converged Services Revenue | C17: ='<<CASH FLOW PROJECTIONS>>'!C17+'<<CASH FLOW PROJECTIONS>>FLTE'!C17 -> 0 | D17: ='<<CASH FLOW PROJECTIONS>>'!D17+'<<CASH FLOW PROJECTIONS>>FLTE'!D17 -> 0 | E17: ='<<CASH FLOW PROJECTIONS>>'!E17+'<<CASH FLOW PROJECTIONS>>FLTE'!E17 -> 0 | F17: ='<<CASH FLOW PROJECTIONS>>'!F17+'<<CASH FLOW PROJECTIONS>>FLTE'!F17 -> 0 | G17: ='<<CASH FLOW PROJECTIONS>>'!G17+'<<CASH FLOW PROJECTIONS>>FLTE'!G17 -> 0 | H17: ='<<CASH FLOW PROJECTIONS>>'!H17+'<<CASH FLOW PROJECTIONS>>FLTE'!H17 -> 0 | I17: ='<<CASH FLOW PROJECTIONS>>'!I17+'<<CASH FLOW PROJECTIONS>>FLTE'!I17 -> 0 | J17: ='<<CASH FLOW PROJECTIONS>>'!J17+'<<CASH FLOW PROJECTIONS>>FLTE'!J17 -> 0 | ... BR17: ='<<CASH FLOW PROJECTIONS>>'!BR17+'<<CASH FLOW PROJECTIONS>>FLTE'!BR17 -> 0
B18: Other Services Revenue | C18: ='<<CASH FLOW PROJECTIONS>>'!C18+'<<CASH FLOW PROJECTIONS>>FLTE'!C18 -> 0 | D18: ='<<CASH FLOW PROJECTIONS>>'!D18+'<<CASH FLOW PROJECTIONS>>FLTE'!D18 -> 0 | E18: ='<<CASH FLOW PROJECTIONS>>'!E18+'<<CASH FLOW PROJECTIONS>>FLTE'!E18 -> 0 | F18: ='<<CASH FLOW PROJECTIONS>>'!F18+'<<CASH FLOW PROJECTIONS>>FLTE'!F18 -> 0 | G18: ='<<CASH FLOW PROJECTIONS>>'!G18+'<<CASH FLOW PROJECTIONS>>FLTE'!G18 -> 0 | H18: ='<<CASH FLOW PROJECTIONS>>'!H18+'<<CASH FLOW PROJECTIONS>>FLTE'!H18 -> 0 | I18: ='<<CASH FLOW PROJECTIONS>>'!I18+'<<CASH FLOW PROJECTIONS>>FLTE'!I18 -> 0 | J18: ='<<CASH FLOW PROJECTIONS>>'!J18+'<<CASH FLOW PROJECTIONS>>FLTE'!J18 -> 0 | ... BR18: ='<<CASH FLOW PROJECTIONS>>'!BR18+'<<CASH FLOW PROJECTIONS>>FLTE'!BR18 -> 0
B19: Bundle Recharge Revenue | C19: ='<<CASH FLOW PROJECTIONS>>'!C19+'<<CASH FLOW PROJECTIONS>>FLTE'!C19 -> 0 | D19: ='<<CASH FLOW PROJECTIONS>>'!D19+'<<CASH FLOW PROJECTIONS>>FLTE'!D19 -> 0 | E19: ='<<CASH FLOW PROJECTIONS>>'!E19+'<<CASH FLOW PROJECTIONS>>FLTE'!E19 -> 0 | F19: ='<<CASH FLOW PROJECTIONS>>'!F19+'<<CASH FLOW PROJECTIONS>>FLTE'!F19 -> 0 | G19: ='<<CASH FLOW PROJECTIONS>>'!G19+'<<CASH FLOW PROJECTIONS>>FLTE'!G19 -> 0 | H19: ='<<CASH FLOW PROJECTIONS>>'!H19+'<<CASH FLOW PROJECTIONS>>FLTE'!H19 -> 0 | I19: ='<<CASH FLOW PROJECTIONS>>'!I19+'<<CASH FLOW PROJECTIONS>>FLTE'!I19 -> 0 | J19: ='<<CASH FLOW PROJECTIONS>>'!J19+'<<CASH FLOW PROJECTIONS>>FLTE'!J19 -> 0 | ... BR19: ='<<CASH FLOW PROJECTIONS>>'!BR19+'<<CASH FLOW PROJECTIONS>>FLTE'!BR19 -> 0
B20: Direct Costs | C20: =SUM(C21:C36) -> 0 | D20: =SUM(D21:D36) -> 0 | E20: =SUM(E21:E36) -> 0 | F20: =SUM(F21:F36) -> 0 | G20: =SUM(G21:G36) -> 0 | H20: =SUM(H21:H36) -> 0 | I20: =SUM(I21:I36) -> 0 | J20: =SUM(J21:J36) -> 135004800 | ... BR20: =SUM(BR21:BR36) -> 1.136693e+10
B21: Marketing | C21: ='<<CASH FLOW PROJECTIONS>>'!C21+'<<CASH FLOW PROJECTIONS>>FLTE'!C21 -> 0 | D21: ='<<CASH FLOW PROJECTIONS>>'!D21+'<<CASH FLOW PROJECTIONS>>FLTE'!D21 -> 0 | E21: ='<<CASH FLOW PROJECTIONS>>'!E21+'<<CASH FLOW PROJECTIONS>>FLTE'!E21 -> 0 | F21: ='<<CASH FLOW PROJECTIONS>>'!F21+'<<CASH FLOW PROJECTIONS>>FLTE'!F21 -> 0 | G21: ='<<CASH FLOW PROJECTIONS>>'!G21+'<<CASH FLOW PROJECTIONS>>FLTE'!G21 -> 0 | H21: ='<<CASH FLOW PROJECTIONS>>'!H21+'<<CASH FLOW PROJECTIONS>>FLTE'!H21 -> 0 | I21: ='<<CASH FLOW PROJECTIONS>>'!I21+'<<CASH FLOW PROJECTIONS>>FLTE'!I21 -> 0 | J21: ='<<CASH FLOW PROJECTIONS>>'!J21+'<<CASH FLOW PROJECTIONS>>FLTE'!J21 -> 0 | ... BR21: ='<<CASH FLOW PROJECTIONS>>'!BR21+'<<CASH FLOW PROJECTIONS>>FLTE'!BR21 -> 3.2359978e+08
B22: Logistics (3PL & Courier) | C22: ='<<CASH FLOW PROJECTIONS>>'!C22+'<<CASH FLOW PROJECTIONS>>FLTE'!C22 -> 0 | D22: ='<<CASH FLOW PROJECTIONS>>'!D22+'<<CASH FLOW PROJECTIONS>>FLTE'!D22 -> 0 | E22: ='<<CASH FLOW PROJECTIONS>>'!E22+'<<CASH FLOW PROJECTIONS>>FLTE'!E22 -> 0 | F22: ='<<CASH FLOW PROJECTIONS>>'!F22+'<<CASH FLOW PROJECTIONS>>FLTE'!F22 -> 0 | G22: ='<<CASH FLOW PROJECTIONS>>'!G22+'<<CASH FLOW PROJECTIONS>>FLTE'!G22 -> 0 | H22: ='<<CASH FLOW PROJECTIONS>>'!H22+'<<CASH FLOW PROJECTIONS>>FLTE'!H22 -> 0 | I22: ='<<CASH FLOW PROJECTIONS>>'!I22+'<<CASH FLOW PROJECTIONS>>FLTE'!I22 -> 0 | J22: ='<<CASH FLOW PROJECTIONS>>'!J22+'<<CASH FLOW PROJECTIONS>>FLTE'!J22 -> 22500000 | ... BR22: ='<<CASH FLOW PROJECTIONS>>'!BR22+'<<CASH FLOW PROJECTIONS>>FLTE'!BR22 -> 31516560
B23: SIM Cards | C23: ='<<CASH FLOW PROJECTIONS>>'!C23+'<<CASH FLOW PROJECTIONS>>FLTE'!C23 -> 0 | D23: ='<<CASH FLOW PROJECTIONS>>'!D23+'<<CASH FLOW PROJECTIONS>>FLTE'!D23 -> 0 | E23: ='<<CASH FLOW PROJECTIONS>>'!E23+'<<CASH FLOW PROJECTIONS>>FLTE'!E23 -> 0 | F23: ='<<CASH FLOW PROJECTIONS>>'!F23+'<<CASH FLOW PROJECTIONS>>FLTE'!F23 -> 0 | G23: ='<<CASH FLOW PROJECTIONS>>'!G23+'<<CASH FLOW PROJECTIONS>>FLTE'!G23 -> 0 | H23: ='<<CASH FLOW PROJECTIONS>>'!H23+'<<CASH FLOW PROJECTIONS>>FLTE'!H23 -> 0 | I23: ='<<CASH FLOW PROJECTIONS>>'!I23+'<<CASH FLOW PROJECTIONS>>FLTE'!I23 -> 0 | J23: ='<<CASH FLOW PROJECTIONS>>'!J23+'<<CASH FLOW PROJECTIONS>>FLTE'!J23 -> 112504800 | ... BR23: ='<<CASH FLOW PROJECTIONS>>'!BR23+'<<CASH FLOW PROJECTIONS>>FLTE'!BR23 -> 157500000
B24: Cash Sale Device Costs | C24: ='<<CASH FLOW PROJECTIONS>>'!C24+'<<CASH FLOW PROJECTIONS>>FLTE'!C24 -> 0 | D24: ='<<CASH FLOW PROJECTIONS>>'!D24+'<<CASH FLOW PROJECTIONS>>FLTE'!D24 -> 0 | E24: ='<<CASH FLOW PROJECTIONS>>'!E24+'<<CASH FLOW PROJECTIONS>>FLTE'!E24 -> 0 | F24: ='<<CASH FLOW PROJECTIONS>>'!F24+'<<CASH FLOW PROJECTIONS>>FLTE'!F24 -> 0 | G24: ='<<CASH FLOW PROJECTIONS>>'!G24+'<<CASH FLOW PROJECTIONS>>FLTE'!G24 -> 0 | H24: ='<<CASH FLOW PROJECTIONS>>'!H24+'<<CASH FLOW PROJECTIONS>>FLTE'!H24 -> 0 | I24: ='<<CASH FLOW PROJECTIONS>>'!I24+'<<CASH FLOW PROJECTIONS>>FLTE'!I24 -> 0 | J24: ='<<CASH FLOW PROJECTIONS>>'!J24+'<<CASH FLOW PROJECTIONS>>FLTE'!J24 -> 0 | ... BR24: ='<<CASH FLOW PROJECTIONS>>'!BR24+'<<CASH FLOW PROJECTIONS>>FLTE'!BR24 -> 0
B25: Credit Device Costs | C25: ='<<CASH FLOW PROJECTIONS>>'!C25+'<<CASH FLOW PROJECTIONS>>FLTE'!C25 -> 0 | D25: ='<<CASH FLOW PROJECTIONS>>'!D25+'<<CASH FLOW PROJECTIONS>>FLTE'!D25 -> 0 | E25: ='<<CASH FLOW PROJECTIONS>>'!E25+'<<CASH FLOW PROJECTIONS>>FLTE'!E25 -> 0 | F25: ='<<CASH FLOW PROJECTIONS>>'!F25+'<<CASH FLOW PROJECTIONS>>FLTE'!F25 -> 0 | G25: ='<<CASH FLOW PROJECTIONS>>'!G25+'<<CASH FLOW PROJECTIONS>>FLTE'!G25 -> 0 | H25: ='<<CASH FLOW PROJECTIONS>>'!H25+'<<CASH FLOW PROJECTIONS>>FLTE'!H25 -> 0 | I25: ='<<CASH FLOW PROJECTIONS>>'!I25+'<<CASH FLOW PROJECTIONS>>FLTE'!I25 -> 0 | J25: ='<<CASH FLOW PROJECTIONS>>'!J25+'<<CASH FLOW PROJECTIONS>>FLTE'!J25 -> 0 | ... BR25: ='<<CASH FLOW PROJECTIONS>>'!BR25+'<<CASH FLOW PROJECTIONS>>FLTE'!BR25 -> 0
B26: Upgrade Costs | C26: ='<<CASH FLOW PROJECTIONS>>'!C26+'<<CASH FLOW PROJECTIONS>>FLTE'!C26 -> 0 | D26: ='<<CASH FLOW PROJECTIONS>>'!D26+'<<CASH FLOW PROJECTIONS>>FLTE'!D26 -> 0 | E26: ='<<CASH FLOW PROJECTIONS>>'!E26+'<<CASH FLOW PROJECTIONS>>FLTE'!E26 -> 0 | F26: ='<<CASH FLOW PROJECTIONS>>'!F26+'<<CASH FLOW PROJECTIONS>>FLTE'!F26 -> 0 | G26: ='<<CASH FLOW PROJECTIONS>>'!G26+'<<CASH FLOW PROJECTIONS>>FLTE'!G26 -> 0 | H26: ='<<CASH FLOW PROJECTIONS>>'!H26+'<<CASH FLOW PROJECTIONS>>FLTE'!H26 -> 0 | I26: ='<<CASH FLOW PROJECTIONS>>'!I26+'<<CASH FLOW PROJECTIONS>>FLTE'!I26 -> 0 | J26: ='<<CASH FLOW PROJECTIONS>>'!J26+'<<CASH FLOW PROJECTIONS>>FLTE'!J26 -> 0 | ... BR26: ='<<CASH FLOW PROJECTIONS>>'!BR26+'<<CASH FLOW PROJECTIONS>>FLTE'!BR26 -> 0
B27: ='DIRECT COST'!B82 -> Channel Upfront Commissions: CIB | C27: ='<<CASH FLOW PROJECTIONS>>'!C27+'<<CASH FLOW PROJECTIONS>>FLTE'!C27 -> 0 | D27: ='<<CASH FLOW PROJECTIONS>>'!D27+'<<CASH FLOW PROJECTIONS>>FLTE'!D27 -> 0 | E27: ='<<CASH FLOW PROJECTIONS>>'!E27+'<<CASH FLOW PROJECTIONS>>FLTE'!E27 -> 0 | F27: ='<<CASH FLOW PROJECTIONS>>'!F27+'<<CASH FLOW PROJECTIONS>>FLTE'!F27 -> 0 | G27: ='<<CASH FLOW PROJECTIONS>>'!G27+'<<CASH FLOW PROJECTIONS>>FLTE'!G27 -> 0 | H27: ='<<CASH FLOW PROJECTIONS>>'!H27+'<<CASH FLOW PROJECTIONS>>FLTE'!H27 -> 0 | I27: ='<<CASH FLOW PROJECTIONS>>'!I27+'<<CASH FLOW PROJECTIONS>>FLTE'!I27 -> 0 | J27: ='<<CASH FLOW PROJECTIONS>>'!J27+'<<CASH FLOW PROJECTIONS>>FLTE'!J27 -> 0 | ... BR27: ='<<CASH FLOW PROJECTIONS>>'!BR27+'<<CASH FLOW PROJECTIONS>>FLTE'!BR27 -> 7.9245925e+08
B28: ='DIRECT COST'!B83 -> Channel Upfront Commissions: Device | C28: ='<<CASH FLOW PROJECTIONS>>'!C28+'<<CASH FLOW PROJECTIONS>>FLTE'!C28 -> 0 | D28: ='<<CASH FLOW PROJECTIONS>>'!D28+'<<CASH FLOW PROJECTIONS>>FLTE'!D28 -> 0 | E28: ='<<CASH FLOW PROJECTIONS>>'!E28+'<<CASH FLOW PROJECTIONS>>FLTE'!E28 -> 0 | F28: ='<<CASH FLOW PROJECTIONS>>'!F28+'<<CASH FLOW PROJECTIONS>>FLTE'!F28 -> 0 | G28: ='<<CASH FLOW PROJECTIONS>>'!G28+'<<CASH FLOW PROJECTIONS>>FLTE'!G28 -> 0 | H28: ='<<CASH FLOW PROJECTIONS>>'!H28+'<<CASH FLOW PROJECTIONS>>FLTE'!H28 -> 0 | I28: ='<<CASH FLOW PROJECTIONS>>'!I28+'<<CASH FLOW PROJECTIONS>>FLTE'!I28 -> 0 | J28: ='<<CASH FLOW PROJECTIONS>>'!J28+'<<CASH FLOW PROJECTIONS>>FLTE'!J28 -> 0 | ... BR28: ='<<CASH FLOW PROJECTIONS>>'!BR28+'<<CASH FLOW PROJECTIONS>>FLTE'!BR28 -> 0
B29: ='DIRECT COST'!B84 -> Channel Ongoing Commission: Subscription | C29: ='<<CASH FLOW PROJECTIONS>>'!C29+'<<CASH FLOW PROJECTIONS>>FLTE'!C29 -> 0 | D29: ='<<CASH FLOW PROJECTIONS>>'!D29+'<<CASH FLOW PROJECTIONS>>FLTE'!D29 -> 0 | E29: ='<<CASH FLOW PROJECTIONS>>'!E29+'<<CASH FLOW PROJECTIONS>>FLTE'!E29 -> 0 | F29: ='<<CASH FLOW PROJECTIONS>>'!F29+'<<CASH FLOW PROJECTIONS>>FLTE'!F29 -> 0 | G29: ='<<CASH FLOW PROJECTIONS>>'!G29+'<<CASH FLOW PROJECTIONS>>FLTE'!G29 -> 0 | H29: ='<<CASH FLOW PROJECTIONS>>'!H29+'<<CASH FLOW PROJECTIONS>>FLTE'!H29 -> 0 | I29: ='<<CASH FLOW PROJECTIONS>>'!I29+'<<CASH FLOW PROJECTIONS>>FLTE'!I29 -> 0 | J29: ='<<CASH FLOW PROJECTIONS>>'!J29+'<<CASH FLOW PROJECTIONS>>FLTE'!J29 -> 0 | ... BR29: ='<<CASH FLOW PROJECTIONS>>'!BR29+'<<CASH FLOW PROJECTIONS>>FLTE'!BR29 -> 0
B30: ='DIRECT COST'!B85 -> Channel Ongoing Commission: Ongoing | C30: ='<<CASH FLOW PROJECTIONS>>'!C30+'<<CASH FLOW PROJECTIONS>>FLTE'!C30 -> 0 | D30: ='<<CASH FLOW PROJECTIONS>>'!D30+'<<CASH FLOW PROJECTIONS>>FLTE'!D30 -> 0 | E30: ='<<CASH FLOW PROJECTIONS>>'!E30+'<<CASH FLOW PROJECTIONS>>FLTE'!E30 -> 0 | F30: ='<<CASH FLOW PROJECTIONS>>'!F30+'<<CASH FLOW PROJECTIONS>>FLTE'!F30 -> 0 | G30: ='<<CASH FLOW PROJECTIONS>>'!G30+'<<CASH FLOW PROJECTIONS>>FLTE'!G30 -> 0 | H30: ='<<CASH FLOW PROJECTIONS>>'!H30+'<<CASH FLOW PROJECTIONS>>FLTE'!H30 -> 0 | I30: ='<<CASH FLOW PROJECTIONS>>'!I30+'<<CASH FLOW PROJECTIONS>>FLTE'!I30 -> 0 | J30: ='<<CASH FLOW PROJECTIONS>>'!J30+'<<CASH FLOW PROJECTIONS>>FLTE'!J30 -> 0 | ... BR30: ='<<CASH FLOW PROJECTIONS>>'!BR30+'<<CASH FLOW PROJECTIONS>>FLTE'!BR30 -> 0
B31: Itemized Billing Costs | C31: ='<<CASH FLOW PROJECTIONS>>'!C31+'<<CASH FLOW PROJECTIONS>>FLTE'!C31 -> 0 | D31: ='<<CASH FLOW PROJECTIONS>>'!D31+'<<CASH FLOW PROJECTIONS>>FLTE'!D31 -> 0 | E31: ='<<CASH FLOW PROJECTIONS>>'!E31+'<<CASH FLOW PROJECTIONS>>FLTE'!E31 -> 0 | F31: ='<<CASH FLOW PROJECTIONS>>'!F31+'<<CASH FLOW PROJECTIONS>>FLTE'!F31 -> 0 | G31: ='<<CASH FLOW PROJECTIONS>>'!G31+'<<CASH FLOW PROJECTIONS>>FLTE'!G31 -> 0 | H31: ='<<CASH FLOW PROJECTIONS>>'!H31+'<<CASH FLOW PROJECTIONS>>FLTE'!H31 -> 0 | I31: ='<<CASH FLOW PROJECTIONS>>'!I31+'<<CASH FLOW PROJECTIONS>>FLTE'!I31 -> 0 | J31: ='<<CASH FLOW PROJECTIONS>>'!J31+'<<CASH FLOW PROJECTIONS>>FLTE'!J31 -> 0 | ... BR31: ='<<CASH FLOW PROJECTIONS>>'!BR31+'<<CASH FLOW PROJECTIONS>>FLTE'!BR31 -> 0
B32: Converged Services Costs | C32: ='<<CASH FLOW PROJECTIONS>>'!C32+'<<CASH FLOW PROJECTIONS>>FLTE'!C32 -> 0 | D32: ='<<CASH FLOW PROJECTIONS>>'!D32+'<<CASH FLOW PROJECTIONS>>FLTE'!D32 -> 0 | E32: ='<<CASH FLOW PROJECTIONS>>'!E32+'<<CASH FLOW PROJECTIONS>>FLTE'!E32 -> 0 | F32: ='<<CASH FLOW PROJECTIONS>>'!F32+'<<CASH FLOW PROJECTIONS>>FLTE'!F32 -> 0 | G32: ='<<CASH FLOW PROJECTIONS>>'!G32+'<<CASH FLOW PROJECTIONS>>FLTE'!G32 -> 0 | H32: ='<<CASH FLOW PROJECTIONS>>'!H32+'<<CASH FLOW PROJECTIONS>>FLTE'!H32 -> 0 | I32: ='<<CASH FLOW PROJECTIONS>>'!I32+'<<CASH FLOW PROJECTIONS>>FLTE'!I32 -> 0 | J32: ='<<CASH FLOW PROJECTIONS>>'!J32+'<<CASH FLOW PROJECTIONS>>FLTE'!J32 -> 0 | ... BR32: ='<<CASH FLOW PROJECTIONS>>'!BR32+'<<CASH FLOW PROJECTIONS>>FLTE'!BR32 -> 0
B33: Other Services Costs | C33: ='<<CASH FLOW PROJECTIONS>>'!C33+'<<CASH FLOW PROJECTIONS>>FLTE'!C33 -> 0 | D33: ='<<CASH FLOW PROJECTIONS>>'!D33+'<<CASH FLOW PROJECTIONS>>FLTE'!D33 -> 0 | E33: ='<<CASH FLOW PROJECTIONS>>'!E33+'<<CASH FLOW PROJECTIONS>>FLTE'!E33 -> 0 | F33: ='<<CASH FLOW PROJECTIONS>>'!F33+'<<CASH FLOW PROJECTIONS>>FLTE'!F33 -> 0 | G33: ='<<CASH FLOW PROJECTIONS>>'!G33+'<<CASH FLOW PROJECTIONS>>FLTE'!G33 -> 0 | H33: ='<<CASH FLOW PROJECTIONS>>'!H33+'<<CASH FLOW PROJECTIONS>>FLTE'!H33 -> 0 | I33: ='<<CASH FLOW PROJECTIONS>>'!I33+'<<CASH FLOW PROJECTIONS>>FLTE'!I33 -> 0 | J33: ='<<CASH FLOW PROJECTIONS>>'!J33+'<<CASH FLOW PROJECTIONS>>FLTE'!J33 -> 0 | ... BR33: ='<<CASH FLOW PROJECTIONS>>'!BR33+'<<CASH FLOW PROJECTIONS>>FLTE'!BR33 -> 0
B34: Wholesale Costs | C34: ='<<CASH FLOW PROJECTIONS>>'!C34+'<<CASH FLOW PROJECTIONS>>FLTE'!C34 -> 0 | D34: ='<<CASH FLOW PROJECTIONS>>'!D34+'<<CASH FLOW PROJECTIONS>>FLTE'!D34 -> 0 | E34: ='<<CASH FLOW PROJECTIONS>>'!E34+'<<CASH FLOW PROJECTIONS>>FLTE'!E34 -> 0 | F34: ='<<CASH FLOW PROJECTIONS>>'!F34+'<<CASH FLOW PROJECTIONS>>FLTE'!F34 -> 0 | G34: ='<<CASH FLOW PROJECTIONS>>'!G34+'<<CASH FLOW PROJECTIONS>>FLTE'!G34 -> 0 | H34: ='<<CASH FLOW PROJECTIONS>>'!H34+'<<CASH FLOW PROJECTIONS>>FLTE'!H34 -> 0 | I34: ='<<CASH FLOW PROJECTIONS>>'!I34+'<<CASH FLOW PROJECTIONS>>FLTE'!I34 -> 0 | J34: ='<<CASH FLOW PROJECTIONS>>'!J34+'<<CASH FLOW PROJECTIONS>>FLTE'!J34 -> 0 | ... BR34: ='<<CASH FLOW PROJECTIONS>>'!BR34+'<<CASH FLOW PROJECTIONS>>FLTE'!BR34 -> 7.2167615e+09
B35: MVNE Cost per Subscriber | C35: ='<<CASH FLOW PROJECTIONS>>'!C35+'<<CASH FLOW PROJECTIONS>>FLTE'!C35 -> 0 | D35: ='<<CASH FLOW PROJECTIONS>>'!D35+'<<CASH FLOW PROJECTIONS>>FLTE'!D35 -> 0 | E35: ='<<CASH FLOW PROJECTIONS>>'!E35+'<<CASH FLOW PROJECTIONS>>FLTE'!E35 -> 0 | F35: ='<<CASH FLOW PROJECTIONS>>'!F35+'<<CASH FLOW PROJECTIONS>>FLTE'!F35 -> 0 | G35: ='<<CASH FLOW PROJECTIONS>>'!G35+'<<CASH FLOW PROJECTIONS>>FLTE'!G35 -> 0 | H35: ='<<CASH FLOW PROJECTIONS>>'!H35+'<<CASH FLOW PROJECTIONS>>FLTE'!H35 -> 0 | I35: ='<<CASH FLOW PROJECTIONS>>'!I35+'<<CASH FLOW PROJECTIONS>>FLTE'!I35 -> 0 | J35: ='<<CASH FLOW PROJECTIONS>>'!J35+'<<CASH FLOW PROJECTIONS>>FLTE'!J35 -> 0 | ... BR35: ='<<CASH FLOW PROJECTIONS>>'!BR35+'<<CASH FLOW PROJECTIONS>>FLTE'!BR35 -> 2.409954e+09
B36: Customer Care Costs | C36: ='<<CASH FLOW PROJECTIONS>>'!C36+'<<CASH FLOW PROJECTIONS>>FLTE'!C36 -> 0 | D36: ='<<CASH FLOW PROJECTIONS>>'!D36+'<<CASH FLOW PROJECTIONS>>FLTE'!D36 -> 0 | E36: ='<<CASH FLOW PROJECTIONS>>'!E36+'<<CASH FLOW PROJECTIONS>>FLTE'!E36 -> 0 | F36: ='<<CASH FLOW PROJECTIONS>>'!F36+'<<CASH FLOW PROJECTIONS>>FLTE'!F36 -> 0 | G36: ='<<CASH FLOW PROJECTIONS>>'!G36+'<<CASH FLOW PROJECTIONS>>FLTE'!G36 -> 0 | H36: ='<<CASH FLOW PROJECTIONS>>'!H36+'<<CASH FLOW PROJECTIONS>>FLTE'!H36 -> 0 | I36: ='<<CASH FLOW PROJECTIONS>>'!I36+'<<CASH FLOW PROJECTIONS>>FLTE'!I36 -> 0 | J36: ='<<CASH FLOW PROJECTIONS>>'!J36+'<<CASH FLOW PROJECTIONS>>FLTE'!J36 -> 0 | ... BR36: ='<<CASH FLOW PROJECTIONS>>'!BR36+'<<CASH FLOW PROJECTIONS>>FLTE'!BR36 -> 4.3513838e+08
B37: Gross Profit | C37: =C8-C20 -> 0 | D37: =D8-D20 -> 0 | E37: =E8-E20 -> 0 | F37: =F8-F20 -> 0 | G37: =G8-G20 -> 0 | H37: =H8-H20 -> 0 | I37: =I8-I20 -> 0 | J37: =J8-J20 -> -135004800 | ... BR37: =BR8-BR20 -> 2.9549112e+09
B38: Gross Profit Percentage (%) | C38: =IF(C37>0,C37/C8,0) -> 0 | D38: =IF(D37>0,D37/D8,0) -> 0 | E38: =IF(E37>0,E37/E8,0) -> 0 | F38: =IF(F37>0,F37/F8,0) -> 0 | G38: =IF(G37>0,G37/G8,0) -> 0 | H38: =IF(H37>0,H37/H8,0) -> 0 | I38: =IF(I37>0,I37/I8,0) -> 0 | J38: =IF(J37>0,J37/J8,0) -> 0 | ... BR38: =IF(BR37>0,BR37/BR8,0) -> 0.20632203
B39: Operational Expenditure | C39: =SUM(C40:C44) -> 1608000000 | D39: =SUM(D40:D44) -> 0 | E39: =SUM(E40:E44) -> 0 | F39: =SUM(F40:F44) -> 48000000 | G39: =SUM(G40:G44) -> 60000000 | H39: =SUM(H40:H44) -> 48000000 | I39: =SUM(I40:I44) -> 81000000 | J39: =SUM(J40:J44) -> 81000000 | ... BR39: =SUM(BR40:BR44) -> 2.5265515e+08
B40: Facilities Costs | C40: ='<<CASH FLOW PROJECTIONS>>'!C41+'<<CASH FLOW PROJECTIONS>>FLTE'!C40 -> 0 | D40: ='<<CASH FLOW PROJECTIONS>>'!D41+'<<CASH FLOW PROJECTIONS>>FLTE'!D40 -> 0 | E40: ='<<CASH FLOW PROJECTIONS>>'!E41+'<<CASH FLOW PROJECTIONS>>FLTE'!E40 -> 0 | F40: ='<<CASH FLOW PROJECTIONS>>'!F41+'<<CASH FLOW PROJECTIONS>>FLTE'!F40 -> 0 | G40: ='<<CASH FLOW PROJECTIONS>>'!G41+'<<CASH FLOW PROJECTIONS>>FLTE'!G40 -> 0 | H40: ='<<CASH FLOW PROJECTIONS>>'!H41+'<<CASH FLOW PROJECTIONS>>FLTE'!H40 -> 0 | I40: ='<<CASH FLOW PROJECTIONS>>'!I41+'<<CASH FLOW PROJECTIONS>>FLTE'!I40 -> 0 | J40: ='<<CASH FLOW PROJECTIONS>>'!J41+'<<CASH FLOW PROJECTIONS>>FLTE'!J40 -> 0 | ... BR40: ='<<CASH FLOW PROJECTIONS>>'!BR41+'<<CASH FLOW PROJECTIONS>>FLTE'!BR40 -> 0
B41: Regulatory Costs | C41: ='<<CASH FLOW PROJECTIONS>>'!C42+'<<CASH FLOW PROJECTIONS>>FLTE'!C41 -> 1608000000 | D41: ='<<CASH FLOW PROJECTIONS>>'!D42+'<<CASH FLOW PROJECTIONS>>FLTE'!D41 -> 0 | E41: ='<<CASH FLOW PROJECTIONS>>'!E42+'<<CASH FLOW PROJECTIONS>>FLTE'!E41 -> 0 | F41: ='<<CASH FLOW PROJECTIONS>>'!F42+'<<CASH FLOW PROJECTIONS>>FLTE'!F41 -> 0 | G41: ='<<CASH FLOW PROJECTIONS>>'!G42+'<<CASH FLOW PROJECTIONS>>FLTE'!G41 -> 0 | H41: ='<<CASH FLOW PROJECTIONS>>'!H42+'<<CASH FLOW PROJECTIONS>>FLTE'!H41 -> 0 | I41: ='<<CASH FLOW PROJECTIONS>>'!I42+'<<CASH FLOW PROJECTIONS>>FLTE'!I41 -> 0 | J41: ='<<CASH FLOW PROJECTIONS>>'!J42+'<<CASH FLOW PROJECTIONS>>FLTE'!J41 -> 0 | ... BR41: ='<<CASH FLOW PROJECTIONS>>'!BR42+'<<CASH FLOW PROJECTIONS>>FLTE'!BR41 -> 1.4289452e+08
B42: Resource Costs | C42: ='<<CASH FLOW PROJECTIONS>>'!C43+'<<CASH FLOW PROJECTIONS>>FLTE'!C42 -> 0 | D42: ='<<CASH FLOW PROJECTIONS>>'!D43+'<<CASH FLOW PROJECTIONS>>FLTE'!D42 -> 0 | E42: ='<<CASH FLOW PROJECTIONS>>'!E43+'<<CASH FLOW PROJECTIONS>>FLTE'!E42 -> 0 | F42: ='<<CASH FLOW PROJECTIONS>>'!F43+'<<CASH FLOW PROJECTIONS>>FLTE'!F42 -> 48000000 | G42: ='<<CASH FLOW PROJECTIONS>>'!G43+'<<CASH FLOW PROJECTIONS>>FLTE'!G42 -> 48000000 | H42: ='<<CASH FLOW PROJECTIONS>>'!H43+'<<CASH FLOW PROJECTIONS>>FLTE'!H42 -> 48000000 | I42: ='<<CASH FLOW PROJECTIONS>>'!I43+'<<CASH FLOW PROJECTIONS>>FLTE'!I42 -> 81000000 | J42: ='<<CASH FLOW PROJECTIONS>>'!J43+'<<CASH FLOW PROJECTIONS>>FLTE'!J42 -> 81000000 | ... BR42: ='<<CASH FLOW PROJECTIONS>>'!BR43+'<<CASH FLOW PROJECTIONS>>FLTE'!BR42 -> 1.0226063e+08
B43: 3rd Party Vendors & Supplier Costs | C43: ='<<CASH FLOW PROJECTIONS>>'!C44+'<<CASH FLOW PROJECTIONS>>FLTE'!C43 -> 0 | D43: ='<<CASH FLOW PROJECTIONS>>'!D44+'<<CASH FLOW PROJECTIONS>>FLTE'!D43 -> 0 | E43: ='<<CASH FLOW PROJECTIONS>>'!E44+'<<CASH FLOW PROJECTIONS>>FLTE'!E43 -> 0 | F43: ='<<CASH FLOW PROJECTIONS>>'!F44+'<<CASH FLOW PROJECTIONS>>FLTE'!F43 -> 0 | G43: ='<<CASH FLOW PROJECTIONS>>'!G44+'<<CASH FLOW PROJECTIONS>>FLTE'!G43 -> 12000000 | H43: ='<<CASH FLOW PROJECTIONS>>'!H44+'<<CASH FLOW PROJECTIONS>>FLTE'!H43 -> 0 | I43: ='<<CASH FLOW PROJECTIONS>>'!I44+'<<CASH FLOW PROJECTIONS>>FLTE'!I43 -> 0 | J43: ='<<CASH FLOW PROJECTIONS>>'!J44+'<<CASH FLOW PROJECTIONS>>FLTE'!J43 -> 0 | ... BR43: ='<<CASH FLOW PROJECTIONS>>'!BR44+'<<CASH FLOW PROJECTIONS>>FLTE'!BR43 -> 0
B44: Other Costs | C44: ='<<CASH FLOW PROJECTIONS>>'!C45+'<<CASH FLOW PROJECTIONS>>FLTE'!C44 -> 0 | D44: ='<<CASH FLOW PROJECTIONS>>'!D45+'<<CASH FLOW PROJECTIONS>>FLTE'!D44 -> 0 | E44: ='<<CASH FLOW PROJECTIONS>>'!E45+'<<CASH FLOW PROJECTIONS>>FLTE'!E44 -> 0 | F44: ='<<CASH FLOW PROJECTIONS>>'!F45+'<<CASH FLOW PROJECTIONS>>FLTE'!F44 -> 0 | G44: ='<<CASH FLOW PROJECTIONS>>'!G45+'<<CASH FLOW PROJECTIONS>>FLTE'!G44 -> 0 | H44: ='<<CASH FLOW PROJECTIONS>>'!H45+'<<CASH FLOW PROJECTIONS>>FLTE'!H44 -> 0 | I44: ='<<CASH FLOW PROJECTIONS>>'!I45+'<<CASH FLOW PROJECTIONS>>FLTE'!I44 -> 0 | J44: ='<<CASH FLOW PROJECTIONS>>'!J45+'<<CASH FLOW PROJECTIONS>>FLTE'!J44 -> 0 | ... BR44: ='<<CASH FLOW PROJECTIONS>>'!BR45+'<<CASH FLOW PROJECTIONS>>FLTE'!BR44 -> 7500000
...

Sheet <<VERSIONING NOTES>>
E2: Prepared for: | F2: Metl
C3: PROJECT VERSIONING NOTES | E3: Version: | F3: MVNE Financial Framework Template Metl 20250604 1m
E4: Author: | F4: Edward Wicks
B6: Versioning Notes & Comments | D6: Changed By | E6: Sheet | F6: Cell
B8: 1
B9: 2
B10: 3 | C10: Sections marked with this colour should calculate automatically
B11: 4 | C11: Sections marked with this colour denote input sections
B12: 5
B13: 6
B14: 7
B15: 8
B16: 9
B17: 10
B18: 11
B19: 12
B20: 13
B21: 14
B22: 15
B23: 16
... B32: 25

Sheet <<KEY FINANCIAL INDICATORS>>
B3: =UPPER('<<VERSIONING NOTES>>'!$F$2)&TEXT(" KEY FINANCIAL INDICATORS VERSION ","")&'<<VERSIONING NOTES>>'!$F$3 -> METL KEY FINANCIAL INDICATORS VERSION MVNE Financial Framework Template Metl 20250604 1m | H3: =TEXT("Prepared by ","") -> Prepared by
H4: ='<<VERSIONING NOTES>>'!F4 -> Edward Wicks
C6: Rewards | D6: Projected | E6: Cumulative EBIT | F6: Cash Flow First | G6: Cash Flow First | H6: Cumulative Revenue
C7: Spend | D7: Peak Funding | E7: over 60 Months | F7: Positive in Month | G7: BreakEven in Month | H7: Over 60 Months
C8: ='<<CASH FLOW PROJECTIONS>>'!BT57 -> 1.2981102e+10 | D8: =ABS(MIN('<<CASH FLOW PROJECTIONS>>'!C63:BR63)) -> 9.7724678e+09 | E8: =H23 -> 3.2411041e+10 | F8: =MIN('<<CASH FLOW PROJECTIONS>>'!C65:BR65) -> 25 | G8: =MIN('<<CASH FLOW PROJECTIONS>>'!C66:BR66) -> 39 | H8: =SUM('<<CASH FLOW PROJECTIONS>>'!C8:BR8) -> 4.3270342e+11
C9: =C8*0.00038 -> 4932818.9 | D9: =D8*0.0004 -> 3908987.1 | E9: =E8*0.0004 -> 12964416 | H9: =H8*0.0004 -> 1.7308137e+08
B10: Projections | C10: Project Phase | D10: Year 1 | E10: Year 2 | F10: Year 3 | G10: Year 4 | H10: Year 5
C11: EBITDA Margin | D11: =D16/D12 -> -0.38269923 | E11: =E16/E12 -> -0.065608481 | F11: =F16/F12 -> 0.10885712 | G11: =G16/G12 -> 0.12766081 | H11: =H16/H12 -> 0.17622897
B12: Revenue | C12: =SUM('<<CASH FLOW PROJECTIONS>>'!C8:H8) -> 0 | D12: =SUM('<<CASH FLOW PROJECTIONS>>'!I8:V8) -> 8.7795904e+09 | E12: =SUM('<<CASH FLOW PROJECTIONS>>'!W8:AH8) -> 3.7494868e+10 | F12: =SUM('<<CASH FLOW PROJECTIONS>>'!AI8:AT8) -> 9.592046e+10 | G12: =SUM('<<CASH FLOW PROJECTIONS>>'!AU8:BF8) -> 1.2870861e+11 | H12: =SUM('<<CASH FLOW PROJECTIONS>>'!BG8:BR8) -> 1.6179989e+11
B13: Direct Costs | C13: =SUM('<<CASH FLOW PROJECTIONS>>'!C20:H20) -> 0 | D13: =SUM('<<CASH FLOW PROJECTIONS>>'!I20:V20) -> 1.0827737e+10 | E13: =SUM('<<CASH FLOW PROJECTIONS>>'!W20:AH20) -> 3.845958e+10 | F13: =SUM('<<CASH FLOW PROJECTIONS>>'!AI20:AT20) -> 8.3337491e+10 | G13: =SUM('<<CASH FLOW PROJECTIONS>>'!AU20:BF20) -> 1.0974281e+11 | H13: =SUM('<<CASH FLOW PROJECTIONS>>'!BG20:BR20) -> 1.3035093e+11
B14: Gross Profit | C14: =C12-C13 -> 0 | D14: =D12-D13 -> -2.0481466e+09 | E14: =E12-E13 -> -9.6471264e+08 | F14: =F12-F13 -> 1.2582969e+10 | G14: =G12-G13 -> 1.8965798e+10 | H14: =H12-H13 -> 3.1448954e+10
B15: Operational Expenditure | C15: =SUM('<<CASH FLOW PROJECTIONS>>'!C40:H40) -> 1764000000 | D15: =SUM('<<CASH FLOW PROJECTIONS>>'!I40:V40) -> 1.3117959e+09 | E15: =SUM('<<CASH FLOW PROJECTIONS>>'!W40:AH40) -> 1.4952687e+09 | F15: =SUM('<<CASH FLOW PROJECTIONS>>'!AI40:AT40) -> 2.1413438e+09 | G15: =SUM('<<CASH FLOW PROJECTIONS>>'!AU40:BF40) -> 2.5347536e+09 | H15: =SUM('<<CASH FLOW PROJECTIONS>>'!BG40:BR40) -> 2.9351265e+09
B16: EBITDA | C16: =C14-C15 -> -1764000000 | D16: =D14-D15 -> -3.3599425e+09 | E16: =E14-E15 -> -2.4599813e+09 | F16: =F14-F15 -> 1.0441625e+10 | G16: =G14-G15 -> 1.6431045e+10 | H16: =H14-H15 -> 2.8513828e+10 | I16: =H16/H12 -> 0.17622897
B17: Capital Expenditure | C17: =SUM('<<CASH FLOW PROJECTIONS>>'!C48:H48) -> 607500000 | D17: =SUM('<<CASH FLOW PROJECTIONS>>'!I48:V48) -> 0 | E17: =SUM('<<CASH FLOW PROJECTIONS>>'!W48:AH48) -> 0 | F17: =SUM('<<CASH FLOW PROJECTIONS>>'!AI48:AT48) -> 0 | G17: =SUM('<<CASH FLOW PROJECTIONS>>'!AU48:BF48) -> 0 | H17: =SUM('<<CASH FLOW PROJECTIONS>>'!BG48:BR48) -> 0
B18: Depreciation | C18: 0 | D18: 0 | E18: 0 | F18: 0 | G18: 0 | H18: 0
B19: Provisions | C19: =SUM('<<CASH FLOW PROJECTIONS>>'!C56:H56) -> 0 | D19: =SUM('<<CASH FLOW PROJECTIONS>>'!I56:V56) -> 2.9996934e+08 | E19: =SUM('<<CASH FLOW PROJECTIONS>>'!W56:AH56) -> 1.2810746e+09 | F19: =SUM('<<CASH FLOW PROJECTIONS>>'!AI56:AT56) -> 3.2772824e+09 | G19: =SUM('<<CASH FLOW PROJECTIONS>>'!AU56:BF56) -> 4.3975441e+09 | H19: =SUM('<<CASH FLOW PROJECTIONS>>'!BG56:BR56) -> 5.5281629e+09
B20: EBIT | C20: =C16-C17-C18-C19 -> -2371500000 | D20: =D16-D17-D18-D19 -> -3.6599118e+09 | E20: =E16-E17-E18-E19 -> -3.741056e+09 | F20: =F16-F17-F18-F19 -> 7.1643429e+09 | G20: =G16-G17-G18-G19 -> 1.2033501e+10 | H20: =H16-H17-H18-H19 -> 2.2985665e+10
D21: =D20/'BASIC INPUT ASSUMPTIONS'!D7 -> -24399412 | E21: =E20/'BASIC INPUT ASSUMPTIONS'!D7 -> -24940373 | F21: =F20/'BASIC INPUT ASSUMPTIONS'!D7 -> 47762286 | G21: =G20/'BASIC INPUT ASSUMPTIONS'!D7 -> 80223337 | H21: =H20/'BASIC INPUT ASSUMPTIONS'!D7 -> 1.5323777e+08
D22: =D20/D12 -> -0.4168659 | E22: =E20/E12 -> -0.099775148 | F22: =F20/F12 -> 0.074690456 | G22: =G20/G12 -> 0.093494139 | H22: =H20/H12 -> 0.1420623
B23: CUMULATIVE EBIT | C23: =C20 -> -2371500000 | D23: =D20+C23 -> -6.0314118e+09 | E23: =E20+D23 -> -9.7724678e+09 | F23: =F20+E23 -> -2.6081249e+09 | G23: =G20+F23 -> 9.4253757e+09 | H23: =H20+G23 -> 3.2411041e+10
B24: Value of the Base | D24: =D28*D30*24 -> 3.8142961e+10 | E24: =E28*E30*24 -> 1.1742075e+11 | F24: =F28*F30*24 -> 2.3483591e+11 | G24: =G28*G30*24 -> 2.8443758e+11 | H24: =H28*H30*24 -> 3.4304683e+11
C25: Susbcriber Base | D25: Year 1 | E25: Year 2 | F25: Year 3 | G25: Year 4 | H25: Year 5
C26: =C29 -> Active Base | D26: =D29 -> 307643.96 | E26: =E29 -> 949105.93 | F26: =F29 -> 1509722.3 | G26: =G29 -> 1801279 | H26: =H29 -> 2006129.8
C27: Opening Base | D27: 0 | E27: =D28 -> 307643.96 | F27: =E28 -> 949105.93 | G27: =F28 -> 1509722.3 | H27: =G28 -> 1831455.4 | J27: Acquisition | K27: 0.75
C28: Closing Base | D28: ='SUBSCRIBER BASE'!W79 -> 307643.96 | E28: ='SUBSCRIBER BASE'!AI79 -> 949105.93 | F28: ='SUBSCRIBER BASE'!AU79 -> 1509722.3 | G28: ='SUBSCRIBER BASE'!BG79 -> 1831455.4 | H28: ='SUBSCRIBER BASE'!BS79 -> 2006129.8 | J28: Churn | K28: 0.6 | L28: =K28/12 -> 0.05
C29: Active Base | D29: ='SUBSCRIBER BASE'!W101 -> 307643.96 | E29: ='SUBSCRIBER BASE'!AI101 -> 949105.93 | F29: ='SUBSCRIBER BASE'!AU101 -> 1509722.3 | G29: ='SUBSCRIBER BASE'!BF101 -> 1801279 | H29: ='SUBSCRIBER BASE'!BS101 -> 2006129.8 | J29: Avg GP | K29: ='MVLP DASHBOARD'!G13 -> 0.39899632 | L29: 1.2
C30: Blended ARPU | D30: =AVERAGE('<<CASH FLOW PROJECTIONS>>'!K68:V68) -> 5166.0044 | E30: =AVERAGE('<<CASH FLOW PROJECTIONS>>'!W68:AH68) -> 5154.8844 | F30: =AVERAGE('<<CASH FLOW PROJECTIONS>>'!AI68:AT68) -> 6481.2114 | G30: =AVERAGE('<<CASH FLOW PROJECTIONS>>'!AU68:BF68) -> 6471.1191 | H30: =AVERAGE('<<CASH FLOW PROJECTIONS>>'!BG68:BR68) -> 7124.9716 | J30: Rewards | K30: 0
C31: Blended ARPU | D31: =D30*0.00038 -> 1.9630817 | E31: =E30*0.00038 -> 1.9588561 | F31: =F30*0.00038 -> 2.4628603 | G31: =G30*0.00038 -> 2.4590253 | H31: =H30*0.00038 -> 2.7074892
C32: CAC | D32: =('MVLP DASHBOARD'!C110+'COMMISSION COSTS'!$K$41+'DIRECT COST'!V7+'BASIC INPUT ASSUMPTIONS'!$D$25)*0.0004 -> 3.0161514 | E32: =('MVLP DASHBOARD'!D110+'COMMISSION COSTS'!$K$41+'DIRECT COST'!AH7+'BASIC INPUT ASSUMPTIONS'!$D$25)*0.0004 -> 1.9524939 | F32: =('MVLP DASHBOARD'!E110+'COMMISSION COSTS'!$K$41+'DIRECT COST'!AT7+'BASIC INPUT ASSUMPTIONS'!$D$25)*0.0004 -> 1.9417578 | G32: =('MVLP DASHBOARD'!F110+'COMMISSION COSTS'!$K$41+'DIRECT COST'!BF7+'BASIC INPUT ASSUMPTIONS'!$D$25)*0.0004 -> 1.9063105 | H32: =('MVLP DASHBOARD'!G110+'COMMISSION COSTS'!$K$41+'DIRECT COST'!BR7+'BASIC INPUT ASSUMPTIONS'!$D$25)*0.0004 -> 1.9116012

Sheet <<CASH FLOW PROJECTIONS>>
B3: =UPPER('<<VERSIONING NOTES>>'!$F$2)&TEXT(" CASH FLOW PROJECTIONS VERSION ","")&'<<VERSIONING NOTES>>'!$F$3 -> METL CASH FLOW PROJECTIONS VERSION MVNE Financial Framework Template Metl 20250604 1m | BR3: =TEXT("Prepared by ","") -> Prepared by
BR4: ='<<VERSIONING NOTES>>'!F4 -> Edward Wicks
C6: PM1 | D6: PM2 | E6: PM3 | F6: PM4 | G6: PM5 | H6: PM6 | I6: SL1 | J6: SL2 | K6: 1 | L6: 2 | M6: 3 | N6: 4 | O6: 5 | P6: 6 | Q6: 7 | R6: 8 | S6: 9 | T6: 10 | U6: 11 | V6: 12 | W6: 13 | X6: 14 | Y6: 15 | Z6: 16 | AA6: 17 | AB6: 18 | AC6: 19 | AD6: 20 | AE6: 21 | AF6: 22 | AG6: 23 | AH6: 24 | AI6: 25 | AJ6: 26 | AK6: 27 | AL6: 28 | AM6: 29 | AN6: 30 | AO6: 31 | AP6: 32 | AQ6: 33 | AR6: 34 | AS6: 35 | AT6: 36 | AU6: 37 | AV6: 38 | AW6: 39 | AX6: 40 | AY6: 41 | AZ6: 42 | BA6: 43 | BB6: 44 | BC6: 45 | BD6: 46 | BE6: 47 | BF6: 48 | BG6: 49 | BH6: 50 | BI6: 51 | BJ6: 52 | BK6: 53 | BL6: 54 | BM6: 55 | BN6: 56 | BO6: 57 | BP6: 58 | BQ6: 59 | BR6: 60
BR7: 1.5
B8: Revenue | C8: =SUM(C9:C19) -> 0 | D8: =SUM(D9:D19) -> 0 | E8: =SUM(E9:E19) -> 0 | F8: =SUM(F9:F19) -> 0 | G8: =SUM(G9:G19) -> 0 | H8: =SUM(H9:H19) -> 0 | I8: =SUM(I9:I19) -> 0 | J8: =SUM(J9:J19) -> 0 | ... BR8: =SUM(BR9:BR19) -> 1.4289452e+10 | BT8: =SUM(C8:BS8) -> 4.3270342e+11 | BU8: =BT8/'BASIC INPUT ASSUMPTIONS'!$D$7 -> 2.8846894e+09 | BV8: =BU8*0.1/19 -> 15182576
B9: Connection Fees | C9: =REVENUE!C8 -> 0 | D9: =REVENUE!D8 -> 0 | E9: =REVENUE!E8 -> 0 | F9: =REVENUE!F8 -> 0 | G9: =REVENUE!G8 -> 0 | H9: =REVENUE!H8 -> 0 | I9: =REVENUE!I8 -> 0 | J9: =REVENUE!J8 -> 0 | ... BR9: =REVENUE!BR8 -> 0
B10: Courier Fees | C10: =REVENUE!C19 -> 0 | D10: =REVENUE!D19 -> 0 | E10: =REVENUE!E19 -> 0 | F10: =REVENUE!F19 -> 0 | G10: =REVENUE!G19 -> 0 | H10: =REVENUE!H19 -> 0 | I10: =REVENUE!I19 -> 0 | J10: =REVENUE!J19 -> 0 | ... BR10: =REVENUE!BR19 -> 0
B11: Cash Device Sales Revenue | C11: =REVENUE!C30 -> 0 | D11: =REVENUE!D30 -> 0 | E11: =REVENUE!E30 -> 0 | F11: =REVENUE!F30 -> 0 | G11: =REVENUE!G30 -> 0 | H11: =REVENUE!H30 -> 0 | I11: =REVENUE!I30 -> 0 | J11: =REVENUE!J30 -> 0 | ... BR11: =REVENUE!BR30 -> 0
B12: Credit Device Pay in Revenue | C12: =REVENUE!C41 -> 0 | D12: =REVENUE!D41 -> 0 | E12: =REVENUE!E41 -> 0 | F12: =REVENUE!F41 -> 0 | G12: =REVENUE!G41 -> 0 | H12: =REVENUE!H41 -> 0 | I12: =REVENUE!I41 -> 0 | J12: =REVENUE!J41 -> 0 | ... BR12: =REVENUE!BR41 -> 0
B13: Device Subscription Revenue | C13: =REVENUE!C52 -> 0 | D13: =REVENUE!D52 -> 0 | E13: =REVENUE!E52 -> 0 | F13: =REVENUE!F52 -> 0 | G13: =REVENUE!G52 -> 0 | H13: =REVENUE!H52 -> 0 | I13: =REVENUE!I52 -> 0 | J13: =REVENUE!J52 -> 0 | ... BR13: =REVENUE!BR52 -> 0
B14: Subscription Revenue | C14: =REVENUE!C63 -> 0 | D14: =REVENUE!D63 -> 0 | E14: =REVENUE!E63 -> 0 | F14: =REVENUE!F63 -> 0 | G14: =REVENUE!G63 -> 0 | H14: =REVENUE!H63 -> 0 | I14: =REVENUE!I63 -> 0 | J14: =REVENUE!J63 -> 0 | ... BR14: =REVENUE!BR63 -> 1.4289452e+10
B15: OOB Spend Revenue | C15: =REVENUE!C74 -> 0 | D15: =REVENUE!D74 -> 0 | E15: =REVENUE!E74 -> 0 | F15: =REVENUE!F74 -> 0 | G15: =REVENUE!G74 -> 0 | H15: =REVENUE!H74 -> 0 | I15: =REVENUE!I74 -> 0 | J15: =REVENUE!J74 -> 0 | ... BR15: =REVENUE!BR74 -> 0
B16: Itemized Billing Revenue | C16: =REVENUE!C85 -> 0 | D16: =REVENUE!D85 -> 0 | E16: =REVENUE!E85 -> 0 | F16: =REVENUE!F85 -> 0 | G16: =REVENUE!G85 -> 0 | H16: =REVENUE!H85 -> 0 | I16: =REVENUE!I85 -> 0 | J16: =REVENUE!J85 -> 0 | ... BR16: =REVENUE!BR85 -> 0
B17: Converged Services Revenue | C17: =REVENUE!C96 -> 0 | D17: =REVENUE!D96 -> 0 | E17: =REVENUE!E96 -> 0 | F17: =REVENUE!F96 -> 0 | G17: =REVENUE!G96 -> 0 | H17: =REVENUE!H96 -> 0 | I17: =REVENUE!I96 -> 0 | J17: =REVENUE!J96 -> 0 | ... BR17: =REVENUE!BR96 -> 0
B18: Other Services Revenue | C18: =REVENUE!C107 -> 0 | D18: =REVENUE!D107 -> 0 | E18: =REVENUE!E107 -> 0 | F18: =REVENUE!F107 -> 0 | G18: =REVENUE!G107 -> 0 | H18: =REVENUE!H107 -> 0 | I18: =REVENUE!I107 -> 0 | J18: =REVENUE!J107 -> 0 | ... BR18: =REVENUE!BR107 -> 0
B19: Bundle Recharge Revenue | C19: =REVENUE!C118 -> 0 | D19: =REVENUE!D118 -> 0 | E19: =REVENUE!E118 -> 0 | F19: =REVENUE!F118 -> 0 | G19: =REVENUE!G118 -> 0 | H19: =REVENUE!H118 -> 0 | I19: =REVENUE!I118 -> 0 | J19: =REVENUE!J118 -> 0 | ... BR19: =REVENUE!BR118 -> 0
B20: Costs | C20: =SUM(C21:C36) -> 0 | D20: =SUM(D21:D36) -> 0 | E20: =SUM(E21:E36) -> 0 | F20: =SUM(F21:F36) -> 0 | G20: =SUM(G21:G36) -> 0 | H20: =SUM(H21:H36) -> 0 | I20: =SUM(I21:I37) -> 0 | J20: =SUM(J21:J37) -> 135000000 | K20: =SUM(K21:K37) -> 3.7188809e+08 | L20: =SUM(L21:L37) -> 2.8760795e+08 | M20: =SUM(M21:M37) -> 3.7141736e+08 | N20: =SUM(N21:N37) -> 5.7748656e+08 | O20: =SUM(O21:O37) -> 6.6032702e+08 | P20: =SUM(P21:P37) -> 7.7834701e+08 | ... BR20: =SUM(BR21:BR37) -> 1.1528564e+10 | BT20: =SUM(C20:BS20) -> 3.7271855e+11 | BU20: =BT20/'BASIC INPUT ASSUMPTIONS'!$D$7 -> 2.4847904e+09
B21: Marketing | C21: ='DIRECT COST'!C8 -> 0 | D21: ='DIRECT COST'!D8 -> 0 | E21: ='DIRECT COST'!E8 -> 0 | F21: ='DIRECT COST'!F8 -> 0 | G21: ='DIRECT COST'!G8 -> 0 | H21: ='DIRECT COST'!H8 -> 0 | I21: ='DIRECT COST'!I8 -> 0 | J21: ='DIRECT COST'!J8 -> 0 | ... BR21: ='DIRECT COST'!BR8 -> 3.2359978e+08 | BU21: ,
B22: Logistics (3PL & Courier) | C22: ='DIRECT COST'!C15 -> 0 | D22: ='DIRECT COST'!D15 -> 0 | E22: ='DIRECT COST'!E15 -> 0 | F22: ='DIRECT COST'!F15 -> 0 | G22: ='DIRECT COST'!G15 -> 0 | H22: ='DIRECT COST'!H15 -> 0 | I22: ='DIRECT COST'!I15 -> 0 | J22: ='DIRECT COST'!J15 -> 22500000 | ... BR22: ='DIRECT COST'!BR15 -> 31500000 | BT22: =SUM(C22:BS22) -> 1350000000 | BU22: =BT22/'BASIC INPUT ASSUMPTIONS'!$D$7 -> 9000000
B23: SIM Cards | C23: ='DIRECT COST'!C38 -> 0 | D23: ='DIRECT COST'!D38 -> 0 | E23: ='DIRECT COST'!E38 -> 0 | F23: ='DIRECT COST'!F38 -> 0 | G23: ='DIRECT COST'!G38 -> 0 | H23: ='DIRECT COST'!H38 -> 0 | I23: ='DIRECT COST'!I38 -> 0 | J23: ='DIRECT COST'!J38 -> 112500000 | ... BR23: ='DIRECT COST'!BR38 -> 157500000 | BT23: =SUM(C23:BS23) -> 6750000000 | BU23: =BT23/'BASIC INPUT ASSUMPTIONS'!$D$7 -> 45000000
B24: Cash Sale Device Costs | C24: ='DIRECT COST'!C49 -> 0 | D24: ='DIRECT COST'!D49 -> 0 | E24: ='DIRECT COST'!E49 -> 0 | F24: ='DIRECT COST'!F49 -> 0 | G24: ='DIRECT COST'!G49 -> 0 | H24: ='DIRECT COST'!H49 -> 0 | I24: ='DIRECT COST'!I49 -> 0 | J24: ='DIRECT COST'!J49 -> 0 | ... BR24: ='DIRECT COST'!BR49 -> 0
B25: Credit Device Costs | C25: ='DIRECT COST'!C60 -> 0 | D25: ='DIRECT COST'!D60 -> 0 | E25: ='DIRECT COST'!E60 -> 0 | F25: ='DIRECT COST'!F60 -> 0 | G25: ='DIRECT COST'!G60 -> 0 | H25: ='DIRECT COST'!H60 -> 0 | I25: ='DIRECT COST'!I60 -> 0 | J25: ='DIRECT COST'!J60 -> 0 | ... BR25: ='DIRECT COST'!BR60 -> 0
B26: Upgrade Costs | C26: ='DIRECT COST'!C71 -> 0 | D26: ='DIRECT COST'!D71 -> 0 | E26: ='DIRECT COST'!E71 -> 0 | F26: ='DIRECT COST'!F71 -> 0 | G26: ='DIRECT COST'!G71 -> 0 | H26: ='DIRECT COST'!H71 -> 0 | I26: ='DIRECT COST'!I71 -> 0 | J26: ='DIRECT COST'!J71 -> 0 | ... BR26: ='DIRECT COST'!BR71 -> 0
B27: ='DIRECT COST'!B82 -> Channel Upfront Commissions: CIB | C27: ='DIRECT COST'!C82 -> 0 | D27: ='DIRECT COST'!D82 -> 0 | E27: ='DIRECT COST'!E82 -> 0 | F27: ='DIRECT COST'!F82 -> 0 | G27: ='DIRECT COST'!G82 -> 0 | H27: ='DIRECT COST'!H82 -> 0 | I27: ='DIRECT COST'!I82 -> 0 | ... BR27: ='DIRECT COST'!BR82 -> 7.9199626e+08
B28: ='DIRECT COST'!B83 -> Channel Upfront Commissions: Device | C28: ='DIRECT COST'!C83 -> 0 | D28: ='DIRECT COST'!D83 -> 0 | E28: ='DIRECT COST'!E83 -> 0 | F28: ='DIRECT COST'!F83 -> 0 | G28: ='DIRECT COST'!G83 -> 0 | H28: ='DIRECT COST'!H83 -> 0 | I28: ='DIRECT COST'!I83 -> 0 | ... BR28: ='DIRECT COST'!BR83 -> 0
B29: ='DIRECT COST'!B84 -> Channel Ongoing Commission: Subscription | C29: ='DIRECT COST'!C84 -> 0 | D29: ='DIRECT COST'!D84 -> 0 | E29: ='DIRECT COST'!E84 -> 0 | F29: ='DIRECT COST'!F84 -> 0 | G29: ='DIRECT COST'!G84 -> 0 | H29: ='DIRECT COST'!H84 -> 0 | I29: ='DIRECT COST'!I84 -> 0 | ... BR29: ='DIRECT COST'!BR84 -> 0
B30: ='DIRECT COST'!B85 -> Channel Ongoing Commission: Ongoing | C30: ='DIRECT COST'!C85 -> 0 | D30: ='DIRECT COST'!D85 -> 0 | E30: ='DIRECT COST'!E85 -> 0 | F30: ='DIRECT COST'!F85 -> 0 | G30: ='DIRECT COST'!G85 -> 0 | H30: ='DIRECT COST'!H85 -> 0 | I30: ='DIRECT COST'!I85 -> 0 | ... BR30: ='DIRECT COST'!BR85 -> 0 | BT30: =SUM(C30:BS30) -> 0 | BU30: =BT30/'BASIC INPUT ASSUMPTIONS'!$D$7 -> 0
B31: Itemized Billing Costs | C31: ='DIRECT COST'!C86 -> 0 | D31: ='DIRECT COST'!D86 -> 0 | E31: ='DIRECT COST'!E86 -> 0 | F31: ='DIRECT COST'!F86 -> 0 | G31: ='DIRECT COST'!G86 -> 0 | H31: ='DIRECT COST'!H86 -> 0 | I31: ='DIRECT COST'!I86 -> 0 | J31: ='DIRECT COST'!J86 -> 0 | ... BR31: ='DIRECT COST'!BR86 -> 0
B32: Converged Services Costs | C32: ='DIRECT COST'!C97 -> 0 | D32: ='DIRECT COST'!D97 -> 0 | E32: ='DIRECT COST'!E97 -> 0 | F32: ='DIRECT COST'!F97 -> 0 | G32: ='DIRECT COST'!G97 -> 0 | H32: ='DIRECT COST'!H97 -> 0 | I32: ='DIRECT COST'!I97 -> 0 | J32: ='DIRECT COST'!J97 -> 0 | ... BR32: ='DIRECT COST'!BR97 -> 0
B33: Other Services Costs | C33: ='DIRECT COST'!C108 -> 0 | D33: ='DIRECT COST'!D108 -> 0 | E33: ='DIRECT COST'!E108 -> 0 | F33: ='DIRECT COST'!F108 -> 0 | G33: ='DIRECT COST'!G108 -> 0 | H33: ='DIRECT COST'!H108 -> 0 | I33: ='DIRECT COST'!I108 -> 0 | J33: ='DIRECT COST'!J108 -> 0 | ... BR33: ='DIRECT COST'!BR108 -> 0
B34: Wholesale Costs | C34: ='DIRECT COST'!C119 -> 0 | D34: ='DIRECT COST'!D119 -> 0 | E34: ='DIRECT COST'!E119 -> 0 | F34: ='DIRECT COST'!F119 -> 0 | G34: ='DIRECT COST'!G119 -> 0 | H34: ='DIRECT COST'!H119 -> 0 | I34: ='DIRECT COST'!I119 -> 0 | J34: ='DIRECT COST'!J119 -> 0 | ... BR34: ='DIRECT COST'!BR119 -> 7.2010519e+09 | BT34: =SUM(C34:BS34) -> 2.2164395e+11 | BU34: =BT34/'BASIC INPUT ASSUMPTIONS'!$D$7 -> 1.4776264e+09 | BV34: =BU34/BU8 -> 0.51223065
B35: MVNE Cost per Subscriber | C35: ='DIRECT COST'!C123 -> 0 | D35: ='DIRECT COST'!D123 -> 0 | E35: ='DIRECT COST'!E123 -> 0 | F35: ='DIRECT COST'!F123 -> 0 | G35: ='DIRECT COST'!G123 -> 0 | H35: ='DIRECT COST'!H123 -> 0 | I35: ='DIRECT COST'!I123 -> 0 | J35: ='DIRECT COST'!J123 -> 0 | ... BR35: ='DIRECT COST'!BR123 -> 2.4073558e+09 | BT35: =SUM(C35:BS35) -> 7.9668052e+10 | BU35: =BT35/'BASIC INPUT ASSUMPTIONS'!$D$7 -> 5.3112035e+08
B36: Customer Care Costs | C36: ='DIRECT COST'!C135 -> 0 | D36: ='DIRECT COST'!D135 -> 0 | E36: ='DIRECT COST'!E135 -> 0 | F36: ='DIRECT COST'!F135 -> 0 | G36: ='DIRECT COST'!G135 -> 0 | H36: ='DIRECT COST'!H135 -> 0 | I36: ='DIRECT COST'!I135 -> 0 | J36: ='DIRECT COST'!J135 -> 0 | ... BR36: ='DIRECT COST'!BR135 -> 4.3482864e+08 | BT36: =SUM(C36:BS36) -> 1.4386671e+10 | BU36: =BT36/'BASIC INPUT ASSUMPTIONS'!$D$7 -> 95911143
B37: KYC | C37: ='DIRECT COST'!C146 -> 0 | D37: ='DIRECT COST'!D146 -> 0 | E37: ='DIRECT COST'!E146 -> 0 | F37: ='DIRECT COST'!F146 -> 0 | G37: ='DIRECT COST'!G146 -> 0 | H37: ='DIRECT COST'!H146 -> 0 | I37: ='DIRECT COST'!I146 -> 0 | J37: ='DIRECT COST'!J146 -> 0 | ... BR37: ='DIRECT COST'!BR146 -> 180732000
B38: Gross Profit | C38: =C8-C20 -> 0 | D38: =D8-D20 -> 0 | E38: =E8-E20 -> 0 | F38: =F8-F20 -> 0 | G38: =G8-G20 -> 0 | H38: =H8-H20 -> 0 | I38: =I8-I20 -> 0 | J38: =J8-J20 -> -135000000 | ... BR38: =BR8-BR20 -> 2.7608871e+09 | BS38: =SUM(C38:BR38) -> 5.9984862e+10
B39: Gross Profit Percentage (%) | C39: =IF(C38>0,C38/C8,0) -> 0 | D39: =IF(D38>0,D38/D8,0) -> 0 | E39: =IF(E38>0,E38/E8,0) -> 0 | F39: =IF(F38>0,F38/F8,0) -> 0 | G39: =IF(G38>0,G38/G8,0) -> 0 | H39: =IF(H38>0,H38/H8,0) -> 0 | I39: =IF(I38>0,I38/I8,0) -> 0 | J39: =IF(J38>0,J38/J8,0) -> 0 | ... BR39: =IF(BR38>0,BR38/BR8,0) -> 0.19321155
B40: Operational Expenditure | C40: =SUM(C41:C45) -> 1608000000 | D40: =SUM(D41:D45) -> 0 | E40: =SUM(E41:E45) -> 0 | F40: =SUM(F41:F45) -> 48000000 | G40: =SUM(G41:G45) -> 60000000 | H40: =SUM(H41:H45) -> 48000000 | I40: =SUM(I41:I45) -> 81000000 | J40: =SUM(J41:J45) -> 81000000 | ... BR40: =SUM(BR41:BR45) -> 2.5265515e+08
B41: Facilities Costs | C41: ='OPERATIONAL EXPENDITURE'!C10 -> 0 | D41: ='OPERATIONAL EXPENDITURE'!D10 -> 0 | E41: ='OPERATIONAL EXPENDITURE'!E10 -> 0 | F41: ='OPERATIONAL EXPENDITURE'!F10 -> 0 | G41: ='OPERATIONAL EXPENDITURE'!G10 -> 0 | H41: ='OPERATIONAL EXPENDITURE'!H10 -> 0 | I41: ='OPERATIONAL EXPENDITURE'!I10 -> 0 | J41: ='OPERATIONAL EXPENDITURE'!J10 -> 0 | ... BR41: ='OPERATIONAL EXPENDITURE'!BR10 -> 0 | BT41: =SUM(C41:BS41) -> 0 | BU41: =BT41/'BASIC INPUT ASSUMPTIONS'!$D$7 -> 0
B42: Regulatory Costs | C42: ='OPERATIONAL EXPENDITURE'!C11 -> 1608000000 | D42: ='OPERATIONAL EXPENDITURE'!D11 -> 0 | E42: ='OPERATIONAL EXPENDITURE'!E11 -> 0 | F42: ='OPERATIONAL EXPENDITURE'!F11 -> 0 | G42: ='OPERATIONAL EXPENDITURE'!G11 -> 0 | H42: ='OPERATIONAL EXPENDITURE'!H11 -> 0 | I42: ='OPERATIONAL EXPENDITURE'!I11 -> 0 | J42: ='OPERATIONAL EXPENDITURE'!J11 -> 0 | ... BR42: ='OPERATIONAL EXPENDITURE'!BR11 -> 1.4289452e+08 | BT42: =SUM(C42:BS42) -> 5.9350342e+09 | BU42: =BT42/'BASIC INPUT ASSUMPTIONS'!$D$7 -> 39566894
B43: Resource Costs | C43: ='OPERATIONAL EXPENDITURE'!C12 -> 0 | D43: ='OPERATIONAL EXPENDITURE'!D12 -> 0 | E43: ='OPERATIONAL EXPENDITURE'!E12 -> 0 | F43: ='OPERATIONAL EXPENDITURE'!F12 -> 48000000 | G43: ='OPERATIONAL EXPENDITURE'!G12 -> 48000000 | H43: ='OPERATIONAL EXPENDITURE'!H12 -> 48000000 | I43: ='OPERATIONAL EXPENDITURE'!I12 -> 81000000 | J43: ='OPERATIONAL EXPENDITURE'!J12 -> 81000000 | ... BR43: ='OPERATIONAL EXPENDITURE'!BR12 -> 1.0226063e+08 | BS43: =BR43/135 -> 757486.18 | BT43: =SUM(C43:BS43) -> 5.7860118e+09 | BU43: =BT43/'BASIC INPUT ASSUMPTIONS'!$D$7 -> 38573412
...

Sheet BASIC INPUT ASSUMPTIONS
C3: KEY INPUT ASSUMPTIONS UNDERPINNING PROVISIONS & THE MODEL
B6: Versioning Notes & Comments | D6: Changed By
C7: FX TZS to ZAR | D7: 150
B8: 1 | C8: VAT Rate for the Client in the Territory | D8: 0.18
B9: 2 | C9: Threshold for Package Profitability (i.e. cannot be less than x%) | D9: 0.25
B10: 3 | C10: Number of Calls Handled by single seat in call centre per month | D10: 2500
B11: 4 | C11: Cost per Seat per Month | D11: =D7*25000 -> 3750000
B12: 5 | C12: Outbound call costs per Customer per month | D12: =4.45*D7 -> 667.5
B13: 6 | C13: Contact Ratio per Month | D13: 0.1
B14: 7 | C14: Provision for Retail Price Erosion per annum expressed as a % of Revenue | D14: 0.05
B15: 8 | C15: Rewards/Loyalty Provision expressed as a % of Revenue | D15: 0.03
B16: 9 | C16: Fraud Provision expressed as a % of Revenue | D16: 0
B17: 10 | C17: MVNE Minimum Monthly Fee | D17: =G17*D7 -> 40500000 | F17: Platform minimum | G17: 270000
B18: 11 | C18: Regulatory fees | D18: 0.01
B19: 12 | C19: Channel Commission | D19: 0.07
B20: 13 | C20: Data wastage | D20: 0
B21: 14 | C21: Voice wastage | D21: 0.5
B22: 15 | C22: SMS Wastage | D22: 0.3
B23: 16 | C23: Marketing | D23: 15%,8%,3.8%,3%,2.4%
B24: 17 | C24: Churn | D24: 0.05
B25: 18 | C25: KYC | D25: =10*'BASIC INPUT ASSUMPTIONS'!D7 -> 1500
B26: 19 | C26: Logistics B to B | D26: 450
B27: 20 | C27: SIM + packaging | D27: 2250
B28: 21 | C28: MVNE per subscriber fee | D28: =8*'BASIC INPUT ASSUMPTIONS'!D7 -> 1200
B29: 22 | C29: MVLP1 - Recharges per sub - Mths 1-24 X 1, mths 25-48 X 6, mths 48-60 X 10
B30: 23 | C30: MVLP2 - Recharges per sub - Mths 1-24 X 1, mths 25-48 X 2
B31: 24 | C31: Blended customer Care fee per sub | D31: =(('BASIC INPUT ASSUMPTIONS'!$D$11/'BASIC INPUT ASSUMPTIONS'!$D$10)+'BASIC INPUT ASSUMPTIONS'!D12)*'BASIC INPUT ASSUMPTIONS'!D13 -> 216.75

Sheet MVLP INPUT
D3: =UPPER('<<VERSIONING NOTES>>'!$F$2)&TEXT(" MINIMUM VIABLE LAUNCH PROPOSITION (MVLP) VERSION ","")&'<<VERSIONING NOTES>>'!$F$3 -> METL MINIMUM VIABLE LAUNCH PROPOSITION (MVLP) VERSION MVNE Financial Framework Template Metl 20250604 1m | N3: =TEXT("Prepared by ","") -> Prepared by
N4: ='<<VERSIONING NOTES>>'!F4 -> Edward Wicks
